Workbook

Sheet Cliente
B1: Chotocruz & Co. · Ficha de cliente
B3: Concepto | C3: Dato numérico | E3: Dato cualitativo
B5: Identificación
B6: Nombre | E6: Cliente de ejemplo
B7: Tipo de documento | E7: Cédula de identidad
B8: Cédula | E8: 1-1234-5678
B9: Fecha de nacimiento | E9: 1980-05-01
B10: Ocupación | E10: Gerente general
B11: Estado civil | E11: Casado(a)
B12: Correo electrónico | E12: ejemplo@ejemplo.com
B13: Teléfono | E13: +506 88887070
B14: País de residencia | E14: Costa Rica
B15: Provincia | E15: Alajuela
B16: Cantón | E16: San Ramón
B17: Distrito | E17: Santiago
B18: Otras señas | E18: —
B19: Edad actual | C19: 46
B20: Edad de independencia financiera | C20: 60
B22: Perfil de riesgo (cuestionario 1)
B23: Tolerancia al riesgo (0 a 10) | C23: 3.0928571 | E23: Preguntas 1, 2, 3, 7 y 9
B24: Apetito de riesgo (0 a 10) | C24: 4.68625 | E24: Preguntas 4, 5, 6, 8 y 10
B25: Puntaje del perfil de riesgo (0 a 10) | C25: 3.9426667
B26: Perfil de riesgo | E26: Moderado conservador
B28: Activos y pasivos (US$, sin la vivienda principal)
B29: Activo: Portafolio de inversión (este portafolio) | C29: 250000 | E29: Liquidez inmediata · declarado en USD
B30: Activo: Pensión voluntaria (saldo) | C30: 26667 | E30: Liquidez media: según el plan de ahorro · declarado en CRC
B31: Activo: FCL (saldo) | C31: 26667 | E31: Liquidez media: cada quinquenio o al terminar la relación laboral · declarado en CRC
B32: Activo: ROP (saldo) | C32: 26667 | E32: Liquidez baja: disponible al pensionarse · declarado en CRC
B33: Activo: Inmueble: Apartamento en Santa Ana | C33: 180000 | E33: Liquidez baja: requiere su venta · declarado en USD
B34: Activo: Empresa: EMPRESA | C34: 900000 | E34: Liquidez baja: participación en una empresa · declarado en USD
B35: Activo: Capital privado (15%) | C35: 120000 | E35: Liquidez muy baja: sin mercado secundario · declarado en USD
B36: Total de activos | C36: 1530000
B37: Pasivo: Deuda: Tarjeta de crédito | C37: 3000 | E37: Corto plazo · termina en 2027 · declarado en USD
B38: Pasivo: Deuda: Préstamo personal | C38: 12000 | E38: Largo plazo · termina en 2029 · declarado en CRC
B39: Pasivo: Hipoteca de la vivienda | C39: 120000 | E39: Largo plazo · termina en 2040 · declarado en USD
B40: Total de pasivos | C40: 135000
B41: Patrimonio neto | C41: 1395000
B42: Peso del portafolio declarado por el cliente | E42: 40% del patrimonio total
B43: Peso del portafolio calculado (control) | E43: 16% de los activos declarados · no interviene en la proyección
B45: Rendimientos del plan
...

Sheet Proyección
B1: Proyección por flujo de caja · Cliente de ejemplo
B2: Arriba, los supuestos (columna F, con su origen en la G) y el resumen de ingresos, gastos, inversiones y desinversiones; a la derecha, el resumen del plan. Debajo, la proyección anual, toda con fórmulas. Los montos se registran, como los declaró el cliente (monto y moneda), en las hojas Ingresos, Gastos, Inversiones y Desinversiones, donde se ve el tipo de cambio aplicado y el monto en dólares; aquí solo se enlazan. Las celdas en color crema son insumos: si se cambian, toda la proyección se recalcula.
B4: Supuestos | I4: Ingresos | R4: Gastos | Z4: Inversiones y desinversiones | AG4: Resumen del plan · toda la proyección
F5: Valor | G5: Origen | L5: Valor declarado | M5: Moneda | N5: Valor usado (US$) | O5: Desde el período | P5: Hasta el período | U5: Valor declarado | V5: Moneda | W5: Valor usado (US$) | X5: Hasta el período | AC5: Valor declarado | AD5: Moneda | AE5: Valor usado (US$)
B6: Supuestos de mercado, del perfil y de la firma | I6: Ingresos ordinarios · hoja «Ingresos» | R6: Gastos ordinarios · hoja «Gastos» | Z6: Inversiones · hoja «Inversiones» | AG6: Flujo · US$ nominales | AL6: Portafolio · US$ nominales
B7: Tipo de cambio ₡/US$ | F7: 450 | G7: Asesor | I7: Ingreso total mensual (actividad) | L7: ='Ingresos'!$D$6 -> 2700000 | M7: ='Ingresos'!$E$6 -> CRC | N7: ='Ingresos'!$G$6 -> 6000 | O7: ='Ingresos'!$H$6 -> 1 | P7: ='Ingresos'!$I$6 -> 14 | R7: Gasto familiar mensual | U7: ='Gastos'!$D$6 -> 5500 | V7: ='Gastos'!$E$6 -> USD | W7: ='Gastos'!$G$6 -> 5500 | Z7: Capital inicial del portafolio | AC7: ='Inversiones'!$D$6 -> 250000 | AD7: ='Inversiones'!$E$6 -> USD | AE7: ='Inversiones'!$G$6 -> 250000 | AG7: Ingresos ordinarios | AJ7: =SUM(M30:M79) -> 5643124 | AL7: Capital inicial | AO7: =AG30 -> 250000
B8: Inflación local (Costa Rica) | F8: 0.039 | G8: Asesor | I8: Ingreso mensual de la pareja | L8: ='Ingresos'!$D$7 -> 0 | M8: ='Ingresos'!$E$7 -> USD | N8: ='Ingresos'!$G$7 -> 0 | O8: ='Ingresos'!$H$7 -> 1 | P8: ='Ingresos'!$I$7 -> 0 | R8: Gasto en el retiro (% del actual, F18) | W8: =$F$18 -> 1 | Z8: Rendimiento esperado (F13) | AE8: =$F$13 -> 0.0585725 | AG8: Ingresos extraordinarios | AJ8: =SUM(P30:P79) -> 283622 | AL8: Flujo neto (ingresos − gastos) | AO8: =SUM(AA30:AA79) -> -5563769
B9: Inflación internacional (EE. UU.) | F9: 0.039 | G9: Asesor | I9: Otros ingresos recurrentes al mes | L9: ='Ingresos'!$D$8 -> 500000 | M9: ='Ingresos'!$E$8 -> CRC | N9: ='Ingresos'!$G$8 -> 1111.11 | O9: ='Ingresos'!$H$8 -> 5 | P9: ='Ingresos'!$I$8 -> 50 | R9: Gastos de dependientes al año | W9: ='Gastos'!G18 -> 12000 | Z9: Desinversiones · hoja «Desinversiones» | AG9: Gastos ordinarios | AJ9: =-SUM(V30:V79) -> -10458610 | AL9: Flujo neto de inversiones (desinversiones) | AO9: =SUM(AF30:AF79) -> 414012
B10: Inflación de la pensión del IVM | F10: 0.01 | G10: Asesor | I10: Pensión del Magisterio (mensual) | L10: ='Pensiones'!$H$6 -> 800000 | M10: ='Pensiones'!$I$6 -> CRC | N10: ='Pensiones'!$K$6 -> 1777.78 | O10: ='Pensiones'!$L$6 -> 20 | R10: Donaciones al año | U10: ='Gastos'!$D$7 -> 3000 | V10: ='Gastos'!$E$7 -> USD | W10: ='Gastos'!$G$7 -> 3000 | Z10: Venta de inmuebles | AE10: ='Desinversiones'!G11 -> 180000 | AG10: Gastos extraordinarios | AJ10: =-SUM(Y30:Y79) -> -1031906 | AL10: Rendimientos del portafolio | AO10: =SUM(AH30:AH79) -> 1310831
B11: Inflación del ROP (aportes al ROP y al FCL) | F11: 0.039 | G11: Asesor | I11: Alquileres de inmuebles al mes | N11: ='Ingresos'!G18 -> 1100 | R11: Cuota mensual de la hipoteca | U11: ='Gastos'!$D$8 -> 1200 | V11: ='Gastos'!$E$8 -> USD | W11: ='Gastos'!$G$8 -> 1200 | X11: ='Gastos'!$I$8 -> 15 | Z11: Venta de la empresa | AE11: ='Desinversiones'!G12 -> 0 | AG11: Flujo neto | AJ11: =SUM(AA30:AA79) -> -5563769 | AL11: Gasto no cubierto por el portafolio | AO11: =SUM(AM30:AM79) -> 3588927
B12: Inflación de la pensión voluntaria | F12: 0.039 | G12: Asesor | I12: Pensión del ROP | L12: Hoja «Pensiones» | R12: Cuotas mensuales de deudas | W12: =IF('Gastos'!$G$28="Sí",0,'Gastos'!G27) -> 500 | Z12: Venta de otros activos | AE12: ='Desinversiones'!G13 -> 150000 | AG12: Resultado | AL12: Saldo final nominal | AO12: =AO7+AO8+AO9+AO10+AO11 -> 0
B13: Rendimiento esperado del portafolio | F13: 0.0585725 | G13: Perfil de riesgo | I13: Pensión voluntaria | L13: Hoja «Pensiones» | R13: Gastos extraordinarios · valor de hoy | AG13: Herencia deseada (US$ de hoy) | AJ13: 0 | AL13: Saldo final en dólares de hoy | AO13: =AK79 -> 0
B14: Rendimiento de los fondos de pensión | F14: 0.06 | G14: Asesor | I14: Ingresos extraordinarios · valor de hoy | R14: Gastos extraordinarios | W14: ='Gastos'!G38 -> 41000 | AG14: Edad a la que se agota el portafolio | AJ14: =IF(AO14>0,SUMPRODUCT(MIN((AM30:AM79>0)*C30:C79+(AM30:AM79<=0)*1000)),"No se agota") -> 79 | AL14: Gasto no cubierto, en dólares de hoy | AO14: =SUMPRODUCT(AM30:AM79/(1+$F$9)^D30:D79) -> 689048
B15: Aporte al ROP (% del salario, si se estima) | F15: 0.0425 | G15: Asesor | I15: Ingresos extraordinarios | N15: ='Ingresos'!G27 -> 160000 | R15: Retiros adicionales del portafolio | W15: ='Retiros del portafolio'!G19 -> 50000 | AG15: ¿Alcanza el plan? | AJ15: =IF(AND(AO14<=0,AO13>=AJ13),"Sí alcanza","No alcanza") -> No alcanza | AL15: Saldo del ROP al final (fuera del portafolio) | AO15: ='Pensiones'!H68 -> 52882
B16: Aporte al FCL (% del salario, si se estima) | F16: 0.015 | G16: Asesor | I16: Traslado del FCL | L16: Hoja «Pensiones» | R16: Metas pagadas con el portafolio | W16: ='Retiros del portafolio'!G10 -> 40000
B17: Datos del cliente
B18: Gasto en el retiro (% del gasto actual) | F18: 1 | G18: Cuestionario
B19: Años hasta la independencia | F19: 14 | G19: Cuestionario
B20: Edad de inicio de la pensión | F20: 65 | G20: Cuestionario
B21: Mes de nacimiento (1 a 12) | F21: 5 | G21: Cuestionario
B22: Gasto familiar pagado en dólares (%) | F22: 0.3 | G22: Cuestionario
B23: Gasto familiar pagado en colones (%) | F23: =1-$F$22 -> 0.7 | G23: El resto
B24: Meses del primer año (1 a 12) | F24: 3 | G24: Fecha del cuestionario
B27: Proyección anual · dólares nominales
B28: Período | F28: Ingresos ordinarios | N28: Ingresos extraordinarios | Q28: Ingresos totales | R28: Gastos ordinarios | W28: Gastos extraordinarios | Z28: Gastos totales | AA28: Flujo neto | AB28: Desinversiones | AF28: Flujo neto de inversiones | AG28: Portafolio
B29: Año | C29: Edad | D29: Período | E29: Fase | F29: Ingreso total (actividad) | G29: Ingreso de la pareja | H29: Otros ingresos recurrentes | I29: Alquileres de inmuebles | J29: Pensión del Magisterio | K29: Pensión del ROP | L29: Pensión voluntaria | M29: Total ingresos ordinarios | N29: Ingresos extraordinarios | O29: Traslado del FCL | P29: Total ingresos extraordinarios | Q29: Total ingresos | R29: Gasto familiar | S29: Gastos de dependientes | T29: Donaciones | U29: Cuotas de hipoteca y deudas | V29: Total gastos ordinarios | W29: Gastos extraordinarios | X29: Inversiones | Y29: Total salidas | Z29: Total gastos | AA29: Flujo neto (ingresos − gastos) | AB29: Venta de inmuebles | AC29: Venta de la empresa | AD29: Venta de otros activos | AE29: Total desinversiones | AF29: Flujo neto de inversiones (desinversiones) | AG29: Portafolio inicial | AH29: Rendimiento | AI29: Flujo neto | AJ29: Portafolio final nominal | AK29: Portafolio en términos reales | AL29: Tasa de retiro (% del portafolio) | AM29: Gasto no cubierto
B30: 2026 | C30: 46 | D30: 1 | E30: =IF(D30<=$F$19,"Acumulación","Retiro") -> Acumulación | F30: =IF(D30<=$P$7,$N$7*12*(1+IF($M$7="CRC",N($F$8),$F$9))^(D30-1),0)*$F$24/12 -> 18000 | G30: =IF(D30<=$P$8,$N$8*12*(1+IF($M$8="CRC",N($F$8),$F$9))^(D30-1),0)*$F$24/12 -> 0 | H30: =IF(AND($N$9>0,D30>=$O$9,D30<=$P$9),$N$9*12*(1+IF($M$9="CRC",N($F$8),$F$9))^(D30-1),0)*$F$24/12 -> 0 | I30: =SUMPRODUCT(('Ingresos'!$H$14:$H$17>=B30)*'Ingresos'!$G$14:$G$17*(1+('Ingresos'!$E$14:$E$17="CRC")*N($F$8)+('Ingresos'!$E$14:$E$17<>"CRC")*$F$9)^(D30-1))*12*$F$24/12 -> 3300 | J30: =IF(AND($N$10>0,D30>=N($O$10)),$N$10*12*(1+IF($M$10="CRC",N($F$8),$F$9))^(N($O$10)-1)*(1+N($F$10))^(D30-N($O$10))*MIN(IF(D30=N($O$10),IF(AND(ISNUMBER($F$21),N($F$20)>=$C$30),(12-$F$21)/12,1),1),$F$24/12),0) -> 0 | K30: ='Pensiones'!T19 -> 0 | L30: ='Pensiones'!U19 -> 0 | M30: =SUM(F30:L30) -> 21300 | N30: =SUMPRODUCT(('Ingresos'!$H$22:$H$26=B30)*'Ingresos'!$G$22:$G$26*(1+('Ingresos'!$E$22:$E$26="CRC")*N($F$8)+('Ingresos'!$E$22:$E$26<>"CRC")*$F$9)^(D30-1)) -> 0 | O30: ='Pensiones'!S19 -> 0 | P30: =SUM(N30:O30) -> 0 | Q30: =M30+P30 -> 21300 | R30: =$W$7*12*(N($F$22)*(1+$F$9)^(D30-1)+(1-N($F$22))*(1+N($F$8))^(D30-1))*IF(D30>$F$19,$F$18,1)*$F$24/12 -> 16500 | S30: =SUMPRODUCT(('Gastos'!$H$14:$H$17<=B30)*('Gastos'!$H$14:$H$17+'Gastos'!$I$14:$I$17>B30)*'Gastos'!$G$14:$G$17*(1+('Gastos'!$E$14:$E$17="CRC")*N($F$8)+('Gastos'!$E$14:$E$17<>"CRC")*$F$9)^(D30-1))*$F$24/12 -> 0 | T30: =$W$10*(1+IF($V$10="CRC",N($F$8),$F$9))^(D30-1)*$F$24/12 -> 750 | U30: =(IF(D30<=$X$11,$W$11*12,0)+IF('Gastos'!$G$28="Sí",0,SUMPRODUCT(('Gastos'!$H$22:$H$26>=B30)*'Gastos'!$G$22:$G$26)*12)+SUMPRODUCT(('Gastos'!$H$43:$H$45<=B30)*('Gastos'!$H$43:$H$45+'Gastos'!$I$43:$I$45-1>=B30)*'Gastos'!$K$43:$K$45))*$F$24/12 -> 5100 | V30: =SUM(R30:U30) -> 22350 | W30: =SUMPRODUCT(('Gastos'!$I$33:$I$37=1)*('Gastos'!$H$33:$H$37=B30)*'Gastos'!$G$33:$G$37*(1+('Gastos'!$E$33:$E$37="CRC")*N($F$8)+('Gastos'!$E$33:$E$37<>"CRC")*$F$9)^(D30-1))+SUMPRODUCT(('Gastos'!$I$33:$I$37=2)*('Gastos'!$H$33:$H$37<=B30)*'Gastos'!$G$33:$G$37*(1+('Gastos'!$E$33:$E$37="CRC")*N($F$8)+('Gastos'!$E$33:$E$37<>"CRC")*$F$9)^(D30-1))*$F$24/12+SUMPRODUCT(('Retiros del portafolio'!$H$15:$H$18=B30)*'Retiros del portafolio'!$G$15:$G$18*(1+('Retiros del portafolio'!$E$15:$E$18="CRC")*N($F$8)+('Retiros del portafolio'!$E$15:$E$18<>"CRC")*$F$9)^(D30-1)) -> 0 | X30: =SUMPRODUCT(('Retiros del portafolio'!$H$6:$H$9=B30)*'Retiros del portafolio'!$G$6:$G$9*(1+('Retiros del portafolio'!$E$6:$E$9="CRC")*N($F$8)+('Retiros del portafolio'!$E$6:$E$9<>"CRC")*$F$9)^(D30-1)) -> 0 | Y30: =W30+X30 -> 0 | Z30: =V30+Y30 -> 22350 | AA30: =Q30-Z30 -> -1050 | AB30: =SUMPRODUCT(('Desinversiones'!$H$6:$H$10=B30)*('Desinversiones'!$I$6:$I$10=1)*'Desinversiones'!$G$6:$G$10*(1+('Desinversiones'!$E$6:$E$10="CRC")*N($F$8)+('Desinversiones'!$E$6:$E$10<>"CRC")*$F$9)^(D30-1)) -> 0 | AC30: =SUMPRODUCT(('Desinversiones'!$H$6:$H$10=B30)*('Desinversiones'!$I$6:$I$10=2)*'Desinversiones'!$G$6:$G$10*(1+('Desinversiones'!$E$6:$E$10="CRC")*N($F$8)+('Desinversiones'!$E$6:$E$10<>"CRC")*$F$9)^(D30-1)) -> 0 | AD30: =SUMPRODUCT(('Desinversiones'!$H$6:$H$10=B30)*('Desinversiones'!$I$6:$I$10=3)*'Desinversiones'!$G$6:$G$10*(1+('Desinversiones'!$E$6:$E$10="CRC")*N($F$8)+('Desinversiones'!$E$6:$E$10<>"CRC")*$F$9)^(D30-1)) -> 0 | AE30: =SUM(AB30:AD30) -> 0 | AF30: =AE30 -> 0 | AG30: =$AE$7 -> 250000 | AH30: =AG30*$F$13*$F$24/12 -> 3661 | AI30: =AA30+AF30 -> -1050 | AJ30: =AG30+AH30+AI30+AM30 -> 252611 | AK30: =AJ30/(1+$F$9)^(D30-1+$F$24/12) -> 250206 | AL30: =IF(AG30<=0,0,MAX(0,-AI30)/AG30) -> 0.0042 | AM30: =MAX(0,-(AG30+AH30+AI30)) -> 0
B31: =B30+1 -> 2027 | C31: =C30+1 -> 47 | D31: =D30+1 -> 2 | E31: =IF(D31<=$F$19,"Acumulación","Retiro") -> Acumulación | F31: =IF(D31<=$P$7,$N$7*12*(1+IF($M$7="CRC",N($F$8),$F$9))^(D31-1),0) -> 74808 | G31: =IF(D31<=$P$8,$N$8*12*(1+IF($M$8="CRC",N($F$8),$F$9))^(D31-1),0) -> 0 | H31: =IF(AND($N$9>0,D31>=$O$9,D31<=$P$9),$N$9*12*(1+IF($M$9="CRC",N($F$8),$F$9))^(D31-1),0) -> 0 | I31: =SUMPRODUCT(('Ingresos'!$H$14:$H$17>=B31)*'Ingresos'!$G$14:$G$17*(1+('Ingresos'!$E$14:$E$17="CRC")*N($F$8)+('Ingresos'!$E$14:$E$17<>"CRC")*$F$9)^(D31-1))*12 -> 13715 | J31: =IF(AND($N$10>0,D31>=N($O$10)),$N$10*12*(1+IF($M$10="CRC",N($F$8),$F$9))^(N($O$10)-1)*(1+N($F$10))^(D31-N($O$10))*IF(D31=N($O$10),IF(AND(ISNUMBER($F$21),N($F$20)>=$C$30),(12-$F$21)/12,1),1),0) -> 0 | K31: ='Pensiones'!T20 -> 0 | L31: ='Pensiones'!U20 -> 0 | M31: =SUM(F31:L31) -> 88523 | N31: =SUMPRODUCT(('Ingresos'!$H$22:$H$26=B31)*'Ingresos'!$G$22:$G$26*(1+('Ingresos'!$E$22:$E$26="CRC")*N($F$8)+('Ingresos'!$E$22:$E$26<>"CRC")*$F$9)^(D31-1)) -> 0 | O31: ='Pensiones'!S20 -> 0 | P31: =SUM(N31:O31) -> 0 | Q31: =M31+P31 -> 88523 | R31: =$W$7*12*(N($F$22)*(1+$F$9)^(D31-1)+(1-N($F$22))*(1+N($F$8))^(D31-1))*IF(D31>$F$19,$F$18,1) -> 68574 | S31: =SUMPRODUCT(('Gastos'!$H$14:$H$17<=B31)*('Gastos'!$H$14:$H$17+'Gastos'!$I$14:$I$17>B31)*'Gastos'!$G$14:$G$17*(1+('Gastos'!$E$14:$E$17="CRC")*N($F$8)+('Gastos'!$E$14:$E$17<>"CRC")*$F$9)^(D31-1)) -> 0 | T31: =$W$10*(1+IF($V$10="CRC",N($F$8),$F$9))^(D31-1) -> 3117 | U31: =(IF(D31<=$X$11,$W$11*12,0)+IF('Gastos'!$G$28="Sí",0,SUMPRODUCT(('Gastos'!$H$22:$H$26>=B31)*'Gastos'!$G$22:$G$26)*12)+SUMPRODUCT(('Gastos'!$H$43:$H$45<=B31)*('Gastos'!$H$43:$H$45+'Gastos'!$I$43:$I$45-1>=B31)*'Gastos'!$K$43:$K$45)) -> 20400 | V31: =SUM(R31:U31) -> 92091 | W31: =SUMPRODUCT(('Gastos'!$I$33:$I$37=1)*('Gastos'!$H$33:$H$37=B31)*'Gastos'!$G$33:$G$37*(1+('Gastos'!$E$33:$E$37="CRC")*N($F$8)+('Gastos'!$E$33:$E$37<>"CRC")*$F$9)^(D31-1))+SUMPRODUCT(('Gastos'!$I$33:$I$37=2)*('Gastos'!$H$33:$H$37<=B31)*'Gastos'!$G$33:$G$37*(1+('Gastos'!$E$33:$E$37="CRC")*N($F$8)+('Gastos'!$E$33:$E$37<>"CRC")*$F$9)^(D31-1))+SUMPRODUCT(('Retiros del portafolio'!$H$15:$H$18=B31)*'Retiros del portafolio'!$G$15:$G$18*(1+('Retiros del portafolio'!$E$15:$E$18="CRC")*N($F$8)+('Retiros del portafolio'!$E$15:$E$18<>"CRC")*$F$9)^(D31-1)) -> 6234 | X31: =SUMPRODUCT(('Retiros del portafolio'!$H$6:$H$9=B31)*'Retiros del portafolio'!$G$6:$G$9*(1+('Retiros del portafolio'!$E$6:$E$9="CRC")*N($F$8)+('Retiros del portafolio'!$E$6:$E$9<>"CRC")*$F$9)^(D31-1)) -> 0 | Y31: =W31+X31 -> 6234 | Z31: =V31+Y31 -> 98325 | AA31: =Q31-Z31 -> -9802 | AB31: =SUMPRODUCT(('Desinversiones'!$H$6:$H$10=B31)*('Desinversiones'!$I$6:$I$10=1)*'Desinversiones'!$G$6:$G$10*(1+('Desinversiones'!$E$6:$E$10="CRC")*N($F$8)+('Desinversiones'!$E$6:$E$10<>"CRC")*$F$9)^(D31-1)) -> 0 | AC31: =SUMPRODUCT(('Desinversiones'!$H$6:$H$10=B31)*('Desinversiones'!$I$6:$I$10=2)*'Desinversiones'!$G$6:$G$10*(1+('Desinversiones'!$E$6:$E$10="CRC")*N($F$8)+('Desinversiones'!$E$6:$E$10<>"CRC")*$F$9)^(D31-1)) -> 0 | AD31: =SUMPRODUCT(('Desinversiones'!$H$6:$H$10=B31)*('Desinversiones'!$I$6:$I$10=3)*'Desinversiones'!$G$6:$G$10*(1+('Desinversiones'!$E$6:$E$10="CRC")*N($F$8)+('Desinversiones'!$E$6:$E$10<>"CRC")*$F$9)^(D31-1)) -> 0 | AE31: =SUM(AB31:AD31) -> 0 | AF31: =AE31 -> 0 | AG31: =AJ30 -> 252611 | AH31: =AG31*$F$13 -> 14796 | AI31: =AA31+AF31 -> -9802 | AJ31: =AG31+AH31+AI31+AM31 -> 257605 | AK31: =AJ31/(1+$F$9)^(D31-1+$F$24/12) -> 245575 | AL31: =IF(AG31<=0,0,MAX(0,-AI31)/AG31) -> 0.038803569 | AM31: =MAX(0,-(AG31+AH31+AI31)) -> 0
B32: =B31+1 -> 2028 | C32: =C31+1 -> 48 | D32: =D31+1 -> 3 | E32: =IF(D32<=$F$19,"Acumulación","Retiro") -> Acumulación | F32: =IF(D32<=$P$7,$N$7*12*(1+IF($M$7="CRC",N($F$8),$F$9))^(D32-1),0) -> 77726 | G32: =IF(D32<=$P$8,$N$8*12*(1+IF($M$8="CRC",N($F$8),$F$9))^(D32-1),0) -> 0 | H32: =IF(AND($N$9>0,D32>=$O$9,D32<=$P$9),$N$9*12*(1+IF($M$9="CRC",N($F$8),$F$9))^(D32-1),0) -> 0 | I32: =SUMPRODUCT(('Ingresos'!$H$14:$H$17>=B32)*'Ingresos'!$G$14:$G$17*(1+('Ingresos'!$E$14:$E$17="CRC")*N($F$8)+('Ingresos'!$E$14:$E$17<>"CRC")*$F$9)^(D32-1))*12 -> 14250 | J32: =IF(AND($N$10>0,D32>=N($O$10)),$N$10*12*(1+IF($M$10="CRC",N($F$8),$F$9))^(N($O$10)-1)*(1+N($F$10))^(D32-N($O$10))*IF(D32=N($O$10),IF(AND(ISNUMBER($F$21),N($F$20)>=$C$30),(12-$F$21)/12,1),1),0) -> 0 | K32: ='Pensiones'!T21 -> 0 | L32: ='Pensiones'!U21 -> 0 | M32: =SUM(F32:L32) -> 91975 | N32: =SUMPRODUCT(('Ingresos'!$H$22:$H$26=B32)*'Ingresos'!$G$22:$G$26*(1+('Ingresos'!$E$22:$E$26="CRC")*N($F$8)+('Ingresos'!$E$22:$E$26<>"CRC")*$F$9)^(D32-1)) -> 43181 | O32: ='Pensiones'!S21 -> 0 | P32: =SUM(N32:O32) -> 43181 | Q32: =M32+P32 -> 135156 | R32: =$W$7*12*(N($F$22)*(1+$F$9)^(D32-1)+(1-N($F$22))*(1+N($F$8))^(D32-1))*IF(D32>$F$19,$F$18,1) -> 71248 | S32: =SUMPRODUCT(('Gastos'!$H$14:$H$17<=B32)*('Gastos'!$H$14:$H$17+'Gastos'!$I$14:$I$17>B32)*'Gastos'!$G$14:$G$17*(1+('Gastos'!$E$14:$E$17="CRC")*N($F$8)+('Gastos'!$E$14:$E$17<>"CRC")*$F$9)^(D32-1)) -> 0 | T32: =$W$10*(1+IF($V$10="CRC",N($F$8),$F$9))^(D32-1) -> 3239 | U32: =(IF(D32<=$X$11,$W$11*12,0)+IF('Gastos'!$G$28="Sí",0,SUMPRODUCT(('Gastos'!$H$22:$H$26>=B32)*'Gastos'!$G$22:$G$26)*12)+SUMPRODUCT(('Gastos'!$H$43:$H$45<=B32)*('Gastos'!$H$43:$H$45+'Gastos'!$I$43:$I$45-1>=B32)*'Gastos'!$K$43:$K$45)) -> 18600 | V32: =SUM(R32:U32) -> 93087 | W32: =SUMPRODUCT(('Gastos'!$I$33:$I$37=1)*('Gastos'!$H$33:$H$37=B32)*'Gastos'!$G$33:$G$37*(1+('Gastos'!$E$33:$E$37="CRC")*N($F$8)+('Gastos'!$E$33:$E$37<>"CRC")*$F$9)^(D32-1))+SUMPRODUCT(('Gastos'!$I$33:$I$37=2)*('Gastos'!$H$33:$H$37<=B32)*'Gastos'!$G$33:$G$37*(1+('Gastos'!$E$33:$E$37="CRC")*N($F$8)+('Gastos'!$E$33:$E$37<>"CRC")*$F$9)^(D32-1))+SUMPRODUCT(('Retiros del portafolio'!$H$15:$H$18=B32)*'Retiros del portafolio'!$G$15:$G$18*(1+('Retiros del portafolio'!$E$15:$E$18="CRC")*N($F$8)+('Retiros del portafolio'!$E$15:$E$18<>"CRC")*$F$9)^(D32-1)) -> 6477 | X32: =SUMPRODUCT(('Retiros del portafolio'!$H$6:$H$9=B32)*'Retiros del portafolio'!$G$6:$G$9*(1+('Retiros del portafolio'!$E$6:$E$9="CRC")*N($F$8)+('Retiros del portafolio'!$E$6:$E$9<>"CRC")*$F$9)^(D32-1)) -> 0 | Y32: =W32+X32 -> 6477 | Z32: =V32+Y32 -> 99564 | AA32: =Q32-Z32 -> 35592 | AB32: =SUMPRODUCT(('Desinversiones'!$H$6:$H$10=B32)*('Desinversiones'!$I$6:$I$10=1)*'Desinversiones'!$G$6:$G$10*(1+('Desinversiones'!$E$6:$E$10="CRC")*N($F$8)+('Desinversiones'!$E$6:$E$10<>"CRC")*$F$9)^(D32-1)) -> 0 | AC32: =SUMPRODUCT(('Desinversiones'!$H$6:$H$10=B32)*('Desinversiones'!$I$6:$I$10=2)*'Desinversiones'!$G$6:$G$10*(1+('Desinversiones'!$E$6:$E$10="CRC")*N($F$8)+('Desinversiones'!$E$6:$E$10<>"CRC")*$F$9)^(D32-1)) -> 0 | AD32: =SUMPRODUCT(('Desinversiones'!$H$6:$H$10=B32)*('Desinversiones'!$I$6:$I$10=3)*'Desinversiones'!$G$6:$G$10*(1+('Desinversiones'!$E$6:$E$10="CRC")*N($F$8)+('Desinversiones'!$E$6:$E$10<>"CRC")*$F$9)^(D32-1)) -> 0 | AE32: =SUM(AB32:AD32) -> 0 | AF32: =AE32 -> 0 | AG32: =AJ31 -> 257605 | AH32: =AG32*$F$13 -> 15089 | AI32: =AA32+AF32 -> 35592 | AJ32: =AG32+AH32+AI32+AM32 -> 308285 | AK32: =AJ32/(1+$F$9)^(D32-1+$F$24/12) -> 282857 | AL32: =IF(AG32<=0,0,MAX(0,-AI32)/AG32) -> 0 | AM32: =MAX(0,-(AG32+AH32+AI32)) -> 0
B33: =B32+1 -> 2029 | C33: =C32+1 -> 49 | D33: =D32+1 -> 4 | E33: =IF(D33<=$F$19,"Acumulación","Retiro") -> Acumulación | F33: =IF(D33<=$P$7,$N$7*12*(1+IF($M$7="CRC",N($F$8),$F$9))^(D33-1),0) -> 80757 | G33: =IF(D33<=$P$8,$N$8*12*(1+IF($M$8="CRC",N($F$8),$F$9))^(D33-1),0) -> 0 | H33: =IF(AND($N$9>0,D33>=$O$9,D33<=$P$9),$N$9*12*(1+IF($M$9="CRC",N($F$8),$F$9))^(D33-1),0) -> 0 | I33: =SUMPRODUCT(('Ingresos'!$H$14:$H$17>=B33)*'Ingresos'!$G$14:$G$17*(1+('Ingresos'!$E$14:$E$17="CRC")*N($F$8)+('Ingresos'!$E$14:$E$17<>"CRC")*$F$9)^(D33-1))*12 -> 14805 | J33: =IF(AND($N$10>0,D33>=N($O$10)),$N$10*12*(1+IF($M$10="CRC",N($F$8),$F$9))^(N($O$10)-1)*(1+N($F$10))^(D33-N($O$10))*IF(D33=N($O$10),IF(AND(ISNUMBER($F$21),N($F$20)>=$C$30),(12-$F$21)/12,1),1),0) -> 0 | K33: ='Pensiones'!T22 -> 0 | L33: ='Pensiones'!U22 -> 0 | M33: =SUM(F33:L33) -> 95562 | N33: =SUMPRODUCT(('Ingresos'!$H$22:$H$26=B33)*'Ingresos'!$G$22:$G$26*(1+('Ingresos'!$E$22:$E$26="CRC")*N($F$8)+('Ingresos'!$E$22:$E$26<>"CRC")*$F$9)^(D33-1)) -> 0 | O33: ='Pensiones'!S22 -> 0 | P33: =SUM(N33:O33) -> 0 | Q33: =M33+P33 -> 95562 | R33: =$W$7*12*(N($F$22)*(1+$F$9)^(D33-1)+(1-N($F$22))*(1+N($F$8))^(D33-1))*IF(D33>$F$19,$F$18,1) -> 74027 | S33: =SUMPRODUCT(('Gastos'!$H$14:$H$17<=B33)*('Gastos'!$H$14:$H$17+'Gastos'!$I$14:$I$17>B33)*'Gastos'!$G$14:$G$17*(1+('Gastos'!$E$14:$E$17="CRC")*N($F$8)+('Gastos'!$E$14:$E$17<>"CRC")*$F$9)^(D33-1)) -> 0 | T33: =$W$10*(1+IF($V$10="CRC",N($F$8),$F$9))^(D33-1) -> 3365 | U33: =(IF(D33<=$X$11,$W$11*12,0)+IF('Gastos'!$G$28="Sí",0,SUMPRODUCT(('Gastos'!$H$22:$H$26>=B33)*'Gastos'!$G$22:$G$26)*12)+SUMPRODUCT(('Gastos'!$H$43:$H$45<=B33)*('Gastos'!$H$43:$H$45+'Gastos'!$I$43:$I$45-1>=B33)*'Gastos'!$K$43:$K$45)) -> 18600 | V33: =SUM(R33:U33) -> 95992 | W33: =SUMPRODUCT(('Gastos'!$I$33:$I$37=1)*('Gastos'!$H$33:$H$37=B33)*'Gastos'!$G$33:$G$37*(1+('Gastos'!$E$33:$E$37="CRC")*N($F$8)+('Gastos'!$E$33:$E$37<>"CRC")*$F$9)^(D33-1))+SUMPRODUCT(('Gastos'!$I$33:$I$37=2)*('Gastos'!$H$33:$H$37<=B33)*'Gastos'!$G$33:$G$37*(1+('Gastos'!$E$33:$E$37="CRC")*N($F$8)+('Gastos'!$E$33:$E$37<>"CRC")*$F$9)^(D33-1))+SUMPRODUCT(('Retiros del portafolio'!$H$15:$H$18=B33)*'Retiros del portafolio'!$G$15:$G$18*(1+('Retiros del portafolio'!$E$15:$E$18="CRC")*N($F$8)+('Retiros del portafolio'!$E$15:$E$18<>"CRC")*$F$9)^(D33-1)) -> 6730 | X33: =SUMPRODUCT(('Retiros del portafolio'!$H$6:$H$9=B33)*'Retiros del portafolio'!$G$6:$G$9*(1+('Retiros del portafolio'!$E$6:$E$9="CRC")*N($F$8)+('Retiros del portafolio'!$E$6:$E$9<>"CRC")*$F$9)^(D33-1)) -> 0 | Y33: =W33+X33 -> 6730 | Z33: =V33+Y33 -> 102722 | AA33: =Q33-Z33 -> -7159 | AB33: =SUMPRODUCT(('Desinversiones'!$H$6:$H$10=B33)*('Desinversiones'!$I$6:$I$10=1)*'Desinversiones'!$G$6:$G$10*(1+('Desinversiones'!$E$6:$E$10="CRC")*N($F$8)+('Desinversiones'!$E$6:$E$10<>"CRC")*$F$9)^(D33-1)) -> 0 | AC33: =SUMPRODUCT(('Desinversiones'!$H$6:$H$10=B33)*('Desinversiones'!$I$6:$I$10=2)*'Desinversiones'!$G$6:$G$10*(1+('Desinversiones'!$E$6:$E$10="CRC")*N($F$8)+('Desinversiones'!$E$6:$E$10<>"CRC")*$F$9)^(D33-1)) -> 0 | AD33: =SUMPRODUCT(('Desinversiones'!$H$6:$H$10=B33)*('Desinversiones'!$I$6:$I$10=3)*'Desinversiones'!$G$6:$G$10*(1+('Desinversiones'!$E$6:$E$10="CRC")*N($F$8)+('Desinversiones'!$E$6:$E$10<>"CRC")*$F$9)^(D33-1)) -> 0 | AE33: =SUM(AB33:AD33) -> 0 | AF33: =AE33 -> 0 | AG33: =AJ32 -> 308285 | AH33: =AG33*$F$13 -> 18057 | AI33: =AA33+AF33 -> -7159 | AJ33: =AG33+AH33+AI33+AM33 -> 319183 | AK33: =AJ33/(1+$F$9)^(D33-1+$F$24/12) -> 281863 | AL33: =IF(AG33<=0,0,MAX(0,-AI33)/AG33) -> 0.023223476 | AM33: =MAX(0,-(AG33+AH33+AI33)) -> 0
B34: =B33+1 -> 2030 | C34: =C33+1 -> 50 | D34: =D33+1 -> 5 | E34: =IF(D34<=$F$19,"Acumulación","Retiro") -> Acumulación | F34: =IF(D34<=$P$7,$N$7*12*(1+IF($M$7="CRC",N($F$8),$F$9))^(D34-1),0) -> 83906 | G34: =IF(D34<=$P$8,$N$8*12*(1+IF($M$8="CRC",N($F$8),$F$9))^(D34-1),0) -> 0 | H34: =IF(AND($N$9>0,D34>=$O$9,D34<=$P$9),$N$9*12*(1+IF($M$9="CRC",N($F$8),$F$9))^(D34-1),0) -> 15538 | I34: =SUMPRODUCT(('Ingresos'!$H$14:$H$17>=B34)*'Ingresos'!$G$14:$G$17*(1+('Ingresos'!$E$14:$E$17="CRC")*N($F$8)+('Ingresos'!$E$14:$E$17<>"CRC")*$F$9)^(D34-1))*12 -> 15383 | J34: =IF(AND($N$10>0,D34>=N($O$10)),$N$10*12*(1+IF($M$10="CRC",N($F$8),$F$9))^(N($O$10)-1)*(1+N($F$10))^(D34-N($O$10))*IF(D34=N($O$10),IF(AND(ISNUMBER($F$21),N($F$20)>=$C$30),(12-$F$21)/12,1),1),0) -> 0 | K34: ='Pensiones'!T23 -> 0 | L34: ='Pensiones'!U23 -> 0 | M34: =SUM(F34:L34) -> 114827 | N34: =SUMPRODUCT(('Ingresos'!$H$22:$H$26=B34)*'Ingresos'!$G$22:$G$26*(1+('Ingresos'!$E$22:$E$26="CRC")*N($F$8)+('Ingresos'!$E$22:$E$26<>"CRC")*$F$9)^(D34-1)) -> 0 | O34: ='Pensiones'!S23 -> 0 | P34: =SUM(N34:O34) -> 0 | Q34: =M34+P34 -> 114827 | R34: =$W$7*12*(N($F$22)*(1+$F$9)^(D34-1)+(1-N($F$22))*(1+N($F$8))^(D34-1))*IF(D34>$F$19,$F$18,1) -> 76914 | S34: =SUMPRODUCT(('Gastos'!$H$14:$H$17<=B34)*('Gastos'!$H$14:$H$17+'Gastos'!$I$14:$I$17>B34)*'Gastos'!$G$14:$G$17*(1+('Gastos'!$E$14:$E$17="CRC")*N($F$8)+('Gastos'!$E$14:$E$17<>"CRC")*$F$9)^(D34-1)) -> 13984 | T34: =$W$10*(1+IF($V$10="CRC",N($F$8),$F$9))^(D34-1) -> 3496 | U34: =(IF(D34<=$X$11,$W$11*12,0)+IF('Gastos'!$G$28="Sí",0,SUMPRODUCT(('Gastos'!$H$22:$H$26>=B34)*'Gastos'!$G$22:$G$26)*12)+SUMPRODUCT(('Gastos'!$H$43:$H$45<=B34)*('Gastos'!$H$43:$H$45+'Gastos'!$I$43:$I$45-1>=B34)*'Gastos'!$K$43:$K$45)) -> 14400 | V34: =SUM(R34:U34) -> 108795 | W34: =SUMPRODUCT(('Gastos'!$I$33:$I$37=1)*('Gastos'!$H$33:$H$37=B34)*'Gastos'!$G$33:$G$37*(1+('Gastos'!$E$33:$E$37="CRC")*N($F$8)+('Gastos'!$E$33:$E$37<>"CRC")*$F$9)^(D34-1))+SUMPRODUCT(('Gastos'!$I$33:$I$37=2)*('Gastos'!$H$33:$H$37<=B34)*'Gastos'!$G$33:$G$37*(1+('Gastos'!$E$33:$E$37="CRC")*N($F$8)+('Gastos'!$E$33:$E$37<>"CRC")*$F$9)^(D34-1))+SUMPRODUCT(('Retiros del portafolio'!$H$15:$H$18=B34)*'Retiros del portafolio'!$G$15:$G$18*(1+('Retiros del portafolio'!$E$15:$E$18="CRC")*N($F$8)+('Retiros del portafolio'!$E$15:$E$18<>"CRC")*$F$9)^(D34-1)) -> 47780 | X34: =SUMPRODUCT(('Retiros del portafolio'!$H$6:$H$9=B34)*'Retiros del portafolio'!$G$6:$G$9*(1+('Retiros del portafolio'!$E$6:$E$9="CRC")*N($F$8)+('Retiros del portafolio'!$E$6:$E$9<>"CRC")*$F$9)^(D34-1)) -> 0 | Y34: =W34+X34 -> 47780 | Z34: =V34+Y34 -> 156575 | AA34: =Q34-Z34 -> -41747 | AB34: =SUMPRODUCT(('Desinversiones'!$H$6:$H$10=B34)*('Desinversiones'!$I$6:$I$10=1)*'Desinversiones'!$G$6:$G$10*(1+('Desinversiones'!$E$6:$E$10="CRC")*N($F$8)+('Desinversiones'!$E$6:$E$10<>"CRC")*$F$9)^(D34-1)) -> 0 | AC34: =SUMPRODUCT(('Desinversiones'!$H$6:$H$10=B34)*('Desinversiones'!$I$6:$I$10=2)*'Desinversiones'!$G$6:$G$10*(1+('Desinversiones'!$E$6:$E$10="CRC")*N($F$8)+('Desinversiones'!$E$6:$E$10<>"CRC")*$F$9)^(D34-1)) -> 0 | AD34: =SUMPRODUCT(('Desinversiones'!$H$6:$H$10=B34)*('Desinversiones'!$I$6:$I$10=3)*'Desinversiones'!$G$6:$G$10*(1+('Desinversiones'!$E$6:$E$10="CRC")*N($F$8)+('Desinversiones'!$E$6:$E$10<>"CRC")*$F$9)^(D34-1)) -> 0 | AE34: =SUM(AB34:AD34) -> 0 | AF34: =AE34 -> 0 | AG34: =AJ33 -> 319183 | AH34: =AG34*$F$13 -> 18695 | AI34: =AA34+AF34 -> -41747 | AJ34: =AG34+AH34+AI34+AM34 -> 296131 | AK34: =AJ34/(1+$F$9)^(D34-1+$F$24/12) -> 251691 | AL34: =IF(AG34<=0,0,MAX(0,-AI34)/AG34) -> 0.1307942 | AM34: =MAX(0,-(AG34+AH34+AI34)) -> 0
B35: =B34+1 -> 2031 | C35: =C34+1 -> 51 | D35: =D34+1 -> 6 | E35: =IF(D35<=$F$19,"Acumulación","Retiro") -> Acumulación | F35: =IF(D35<=$P$7,$N$7*12*(1+IF($M$7="CRC",N($F$8),$F$9))^(D35-1),0) -> 87179 | G35: =IF(D35<=$P$8,$N$8*12*(1+IF($M$8="CRC",N($F$8),$F$9))^(D35-1),0) -> 0 | H35: =IF(AND($N$9>0,D35>=$O$9,D35<=$P$9),$N$9*12*(1+IF($M$9="CRC",N($F$8),$F$9))^(D35-1),0) -> 16144 | I35: =SUMPRODUCT(('Ingresos'!$H$14:$H$17>=B35)*'Ingresos'!$G$14:$G$17*(1+('Ingresos'!$E$14:$E$17="CRC")*N($F$8)+('Ingresos'!$E$14:$E$17<>"CRC")*$F$9)^(D35-1))*12 -> 0 | J35: =IF(AND($N$10>0,D35>=N($O$10)),$N$10*12*(1+IF($M$10="CRC",N($F$8),$F$9))^(N($O$10)-1)*(1+N($F$10))^(D35-N($O$10))*IF(D35=N($O$10),IF(AND(ISNUMBER($F$21),N($F$20)>=$C$30),(12-$F$21)/12,1),1),0) -> 0 | K35: ='Pensiones'!T24 -> 0 | L35: ='Pensiones'!U24 -> 0 | M35: =SUM(F35:L35) -> 103323 | N35: =SUMPRODUCT(('Ingresos'!$H$22:$H$26=B35)*'Ingresos'!$G$22:$G$26*(1+('Ingresos'!$E$22:$E$26="CRC")*N($F$8)+('Ingresos'!$E$22:$E$26<>"CRC")*$F$9)^(D35-1)) -> 0 | O35: ='Pensiones'!S24 -> 0 | P35: =SUM(N35:O35) -> 0 | Q35: =M35+P35 -> 103323 | R35: =$W$7*12*(N($F$22)*(1+$F$9)^(D35-1)+(1-N($F$22))*(1+N($F$8))^(D35-1))*IF(D35>$F$19,$F$18,1) -> 79914 | S35: =SUMPRODUCT(('Gastos'!$H$14:$H$17<=B35)*('Gastos'!$H$14:$H$17+'Gastos'!$I$14:$I$17>B35)*'Gastos'!$G$14:$G$17*(1+('Gastos'!$E$14:$E$17="CRC")*N($F$8)+('Gastos'!$E$14:$E$17<>"CRC")*$F$9)^(D35-1)) -> 14530 | T35: =$W$10*(1+IF($V$10="CRC",N($F$8),$F$9))^(D35-1) -> 3632 | U35: =(IF(D35<=$X$11,$W$11*12,0)+IF('Gastos'!$G$28="Sí",0,SUMPRODUCT(('Gastos'!$H$22:$H$26>=B35)*'Gastos'!$G$22:$G$26)*12)+SUMPRODUCT(('Gastos'!$H$43:$H$45<=B35)*('Gastos'!$H$43:$H$45+'Gastos'!$I$43:$I$45-1>=B35)*'Gastos'!$K$43:$K$45)) -> 14400 | V35: =SUM(R35:U35) -> 112476 | W35: =SUMPRODUCT(('Gastos'!$I$33:$I$37=1)*('Gastos'!$H$33:$H$37=B35)*'Gastos'!$G$33:$G$37*(1+('Gastos'!$E$33:$E$37="CRC")*N($F$8)+('Gastos'!$E$33:$E$37<>"CRC")*$F$9)^(D35-1))+SUMPRODUCT(('Gastos'!$I$33:$I$37=2)*('Gastos'!$H$33:$H$37<=B35)*'Gastos'!$G$33:$G$37*(1+('Gastos'!$E$33:$E$37="CRC")*N($F$8)+('Gastos'!$E$33:$E$37<>"CRC")*$F$9)^(D35-1))+SUMPRODUCT(('Retiros del portafolio'!$H$15:$H$18=B35)*'Retiros del portafolio'!$G$15:$G$18*(1+('Retiros del portafolio'!$E$15:$E$18="CRC")*N($F$8)+('Retiros del portafolio'!$E$15:$E$18<>"CRC")*$F$9)^(D35-1)) -> 67806 | X35: =SUMPRODUCT(('Retiros del portafolio'!$H$6:$H$9=B35)*'Retiros del portafolio'!$G$6:$G$9*(1+('Retiros del portafolio'!$E$6:$E$9="CRC")*N($F$8)+('Retiros del portafolio'!$E$6:$E$9<>"CRC")*$F$9)^(D35-1)) -> 48433 | Y35: =W35+X35 -> 116238 | Z35: =V35+Y35 -> 228714 | AA35: =Q35-Z35 -> -125391 | AB35: =SUMPRODUCT(('Desinversiones'!$H$6:$H$10=B35)*('Desinversiones'!$I$6:$I$10=1)*'Desinversiones'!$G$6:$G$10*(1+('Desinversiones'!$E$6:$E$10="CRC")*N($F$8)+('Desinversiones'!$E$6:$E$10<>"CRC")*$F$9)^(D35-1)) -> 217947 | AC35: =SUMPRODUCT(('Desinversiones'!$H$6:$H$10=B35)*('Desinversiones'!$I$6:$I$10=2)*'Desinversiones'!$G$6:$G$10*(1+('Desinversiones'!$E$6:$E$10="CRC")*N($F$8)+('Desinversiones'!$E$6:$E$10<>"CRC")*$F$9)^(D35-1)) -> 0 | AD35: =SUMPRODUCT(('Desinversiones'!$H$6:$H$10=B35)*('Desinversiones'!$I$6:$I$10=3)*'Desinversiones'!$G$6:$G$10*(1+('Desinversiones'!$E$6:$E$10="CRC")*N($F$8)+('Desinversiones'!$E$6:$E$10<>"CRC")*$F$9)^(D35-1)) -> 0 | AE35: =SUM(AB35:AD35) -> 217947 | AF35: =AE35 -> 217947 | AG35: =AJ34 -> 296131 | AH35: =AG35*$F$13 -> 17345 | AI35: =AA35+AF35 -> 92555 | AJ35: =AG35+AH35+AI35+AM35 -> 406031 | AK35: =AJ35/(1+$F$9)^(D35-1+$F$24/12) -> 332145 | AL35: =IF(AG35<=0,0,MAX(0,-AI35)/AG35) -> 0 | AM35: =MAX(0,-(AG35+AH35+AI35)) -> 0
B36: =B35+1 -> 2032 | C36: =C35+1 -> 52 | D36: =D35+1 -> 7 | E36: =IF(D36<=$F$19,"Acumulación","Retiro") -> Acumulación | F36: =IF(D36<=$P$7,$N$7*12*(1+IF($M$7="CRC",N($F$8),$F$9))^(D36-1),0) -> 90579 | G36: =IF(D36<=$P$8,$N$8*12*(1+IF($M$8="CRC",N($F$8),$F$9))^(D36-1),0) -> 0 | H36: =IF(AND($N$9>0,D36>=$O$9,D36<=$P$9),$N$9*12*(1+IF($M$9="CRC",N($F$8),$F$9))^(D36-1),0) -> 16774 | I36: =SUMPRODUCT(('Ingresos'!$H$14:$H$17>=B36)*'Ingresos'!$G$14:$G$17*(1+('Ingresos'!$E$14:$E$17="CRC")*N($F$8)+('Ingresos'!$E$14:$E$17<>"CRC")*$F$9)^(D36-1))*12 -> 0 | J36: =IF(AND($N$10>0,D36>=N($O$10)),$N$10*12*(1+IF($M$10="CRC",N($F$8),$F$9))^(N($O$10)-1)*(1+N($F$10))^(D36-N($O$10))*IF(D36=N($O$10),IF(AND(ISNUMBER($F$21),N($F$20)>=$C$30),(12-$F$21)/12,1),1),0) -> 0 | K36: ='Pensiones'!T25 -> 0 | L36: ='Pensiones'!U25 -> 0 | M36: =SUM(F36:L36) -> 107352 | N36: =SUMPRODUCT(('Ingresos'!$H$22:$H$26=B36)*'Ingresos'!$G$22:$G$26*(1+('Ingresos'!$E$22:$E$26="CRC")*N($F$8)+('Ingresos'!$E$22:$E$26<>"CRC")*$F$9)^(D36-1)) -> 150964 | O36: ='Pensiones'!S25 -> 0 | P36: =SUM(N36:O36) -> 150964 | Q36: =M36+P36 -> 258317 | R36: =$W$7*12*(N($F$22)*(1+$F$9)^(D36-1)+(1-N($F$22))*(1+N($F$8))^(D36-1))*IF(D36>$F$19,$F$18,1) -> 83030 | S36: =SUMPRODUCT(('Gastos'!$H$14:$H$17<=B36)*('Gastos'!$H$14:$H$17+'Gastos'!$I$14:$I$17>B36)*'Gastos'!$G$14:$G$17*(1+('Gastos'!$E$14:$E$17="CRC")*N($F$8)+('Gastos'!$E$14:$E$17<>"CRC")*$F$9)^(D36-1)) -> 15096 | T36: =$W$10*(1+IF($V$10="CRC",N($F$8),$F$9))^(D36-1) -> 3774 | U36: =(IF(D36<=$X$11,$W$11*12,0)+IF('Gastos'!$G$28="Sí",0,SUMPRODUCT(('Gastos'!$H$22:$H$26>=B36)*'Gastos'!$G$22:$G$26)*12)+SUMPRODUCT(('Gastos'!$H$43:$H$45<=B36)*('Gastos'!$H$43:$H$45+'Gastos'!$I$43:$I$45-1>=B36)*'Gastos'!$K$43:$K$45)) -> 14400 | V36: =SUM(R36:U36) -> 116301 | W36: =SUMPRODUCT(('Gastos'!$I$33:$I$37=1)*('Gastos'!$H$33:$H$37=B36)*'Gastos'!$G$33:$G$37*(1+('Gastos'!$E$33:$E$37="CRC")*N($F$8)+('Gastos'!$E$33:$E$37<>"CRC")*$F$9)^(D36-1))+SUMPRODUCT(('Gastos'!$I$33:$I$37=2)*('Gastos'!$H$33:$H$37<=B36)*'Gastos'!$G$33:$G$37*(1+('Gastos'!$E$33:$E$37="CRC")*N($F$8)+('Gastos'!$E$33:$E$37<>"CRC")*$F$9)^(D36-1))+SUMPRODUCT(('Retiros del portafolio'!$H$15:$H$18=B36)*'Retiros del portafolio'!$G$15:$G$18*(1+('Retiros del portafolio'!$E$15:$E$18="CRC")*N($F$8)+('Retiros del portafolio'!$E$15:$E$18<>"CRC")*$F$9)^(D36-1)) -> 7548 | X36: =SUMPRODUCT(('Retiros del portafolio'!$H$6:$H$9=B36)*'Retiros del portafolio'!$G$6:$G$9*(1+('Retiros del portafolio'!$E$6:$E$9="CRC")*N($F$8)+('Retiros del portafolio'!$E$6:$E$9<>"CRC")*$F$9)^(D36-1)) -> 0 | Y36: =W36+X36 -> 7548 | Z36: =V36+Y36 -> 123849 | AA36: =Q36-Z36 -> 134468 | AB36: =SUMPRODUCT(('Desinversiones'!$H$6:$H$10=B36)*('Desinversiones'!$I$6:$I$10=1)*'Desinversiones'!$G$6:$G$10*(1+('Desinversiones'!$E$6:$E$10="CRC")*N($F$8)+('Desinversiones'!$E$6:$E$10<>"CRC")*$F$9)^(D36-1)) -> 0 | AC36: =SUMPRODUCT(('Desinversiones'!$H$6:$H$10=B36)*('Desinversiones'!$I$6:$I$10=2)*'Desinversiones'!$G$6:$G$10*(1+('Desinversiones'!$E$6:$E$10="CRC")*N($F$8)+('Desinversiones'!$E$6:$E$10<>"CRC")*$F$9)^(D36-1)) -> 0 | AD36: =SUMPRODUCT(('Desinversiones'!$H$6:$H$10=B36)*('Desinversiones'!$I$6:$I$10=3)*'Desinversiones'!$G$6:$G$10*(1+('Desinversiones'!$E$6:$E$10="CRC")*N($F$8)+('Desinversiones'!$E$6:$E$10<>"CRC")*$F$9)^(D36-1)) -> 0 | AE36: =SUM(AB36:AD36) -> 0 | AF36: =AE36 -> 0 | AG36: =AJ35 -> 406031 | AH36: =AG36*$F$13 -> 23782 | AI36: =AA36+AF36 -> 134468 | AJ36: =AG36+AH36+AI36+AM36 -> 564281 | AK36: =AJ36/(1+$F$9)^(D36-1+$F$24/12) -> 444271 | AL36: =IF(AG36<=0,0,MAX(0,-AI36)/AG36) -> 0 | AM36: =MAX(0,-(AG36+AH36+AI36)) -> 0
B37: =B36+1 -> 2033 | C37: =C36+1 -> 53 | D37: =D36+1 -> 8 | E37: =IF(D37<=$F$19,"Acumulación","Retiro") -> Acumulación | F37: =IF(D37<=$P$7,$N$7*12*(1+IF($M$7="CRC",N($F$8),$F$9))^(D37-1),0) -> 94111 | G37: =IF(D37<=$P$8,$N$8*12*(1+IF($M$8="CRC",N($F$8),$F$9))^(D37-1),0) -> 0 | H37: =IF(AND($N$9>0,D37>=$O$9,D37<=$P$9),$N$9*12*(1+IF($M$9="CRC",N($F$8),$F$9))^(D37-1),0) -> 17428 | I37: =SUMPRODUCT(('Ingresos'!$H$14:$H$17>=B37)*'Ingresos'!$G$14:$G$17*(1+('Ingresos'!$E$14:$E$17="CRC")*N($F$8)+('Ingresos'!$E$14:$E$17<>"CRC")*$F$9)^(D37-1))*12 -> 0 | J37: =IF(AND($N$10>0,D37>=N($O$10)),$N$10*12*(1+IF($M$10="CRC",N($F$8),$F$9))^(N($O$10)-1)*(1+N($F$10))^(D37-N($O$10))*IF(D37=N($O$10),IF(AND(ISNUMBER($F$21),N($F$20)>=$C$30),(12-$F$21)/12,1),1),0) -> 0 | K37: ='Pensiones'!T26 -> 0 | L37: ='Pensiones'!U26 -> 0 | M37: =SUM(F37:L37) -> 111539 | N37: =SUMPRODUCT(('Ingresos'!$H$22:$H$26=B37)*'Ingresos'!$G$22:$G$26*(1+('Ingresos'!$E$22:$E$26="CRC")*N($F$8)+('Ingresos'!$E$22:$E$26<>"CRC")*$F$9)^(D37-1)) -> 0 | O37: ='Pensiones'!S26 -> 0 | P37: =SUM(N37:O37) -> 0 | Q37: =M37+P37 -> 111539 | R37: =$W$7*12*(N($F$22)*(1+$F$9)^(D37-1)+(1-N($F$22))*(1+N($F$8))^(D37-1))*IF(D37>$F$19,$F$18,1) -> 86269 | S37: =SUMPRODUCT(('Gastos'!$H$14:$H$17<=B37)*('Gastos'!$H$14:$H$17+'Gastos'!$I$14:$I$17>B37)*'Gastos'!$G$14:$G$17*(1+('Gastos'!$E$14:$E$17="CRC")*N($F$8)+('Gastos'!$E$14:$E$17<>"CRC")*$F$9)^(D37-1)) -> 15685 | T37: =$W$10*(1+IF($V$10="CRC",N($F$8),$F$9))^(D37-1) -> 3921 | U37: =(IF(D37<=$X$11,$W$11*12,0)+IF('Gastos'!$G$28="Sí",0,SUMPRODUCT(('Gastos'!$H$22:$H$26>=B37)*'Gastos'!$G$22:$G$26)*12)+SUMPRODUCT(('Gastos'!$H$43:$H$45<=B37)*('Gastos'!$H$43:$H$45+'Gastos'!$I$43:$I$45-1>=B37)*'Gastos'!$K$43:$K$45)) -> 14400 | V37: =SUM(R37:U37) -> 120275 | W37: =SUMPRODUCT(('Gastos'!$I$33:$I$37=1)*('Gastos'!$H$33:$H$37=B37)*'Gastos'!$G$33:$G$37*(1+('Gastos'!$E$33:$E$37="CRC")*N($F$8)+('Gastos'!$E$33:$E$37<>"CRC")*$F$9)^(D37-1))+SUMPRODUCT(('Gastos'!$I$33:$I$37=2)*('Gastos'!$H$33:$H$37<=B37)*'Gastos'!$G$33:$G$37*(1+('Gastos'!$E$33:$E$37="CRC")*N($F$8)+('Gastos'!$E$33:$E$37<>"CRC")*$F$9)^(D37-1))+SUMPRODUCT(('Retiros del portafolio'!$H$15:$H$18=B37)*'Retiros del portafolio'!$G$15:$G$18*(1+('Retiros del portafolio'!$E$15:$E$18="CRC")*N($F$8)+('Retiros del portafolio'!$E$15:$E$18<>"CRC")*$F$9)^(D37-1)) -> 7843 | X37: =SUMPRODUCT(('Retiros del portafolio'!$H$6:$H$9=B37)*'Retiros del portafolio'!$G$6:$G$9*(1+('Retiros del portafolio'!$E$6:$E$9="CRC")*N($F$8)+('Retiros del portafolio'!$E$6:$E$9<>"CRC")*$F$9)^(D37-1)) -> 0 | Y37: =W37+X37 -> 7843 | Z37: =V37+Y37 -> 128118 | AA37: =Q37-Z37 -> -16579 | AB37: =SUMPRODUCT(('Desinversiones'!$H$6:$H$10=B37)*('Desinversiones'!$I$6:$I$10=1)*'Desinversiones'!$G$6:$G$10*(1+('Desinversiones'!$E$6:$E$10="CRC")*N($F$8)+('Desinversiones'!$E$6:$E$10<>"CRC")*$F$9)^(D37-1)) -> 0 | AC37: =SUMPRODUCT(('Desinversiones'!$H$6:$H$10=B37)*('Desinversiones'!$I$6:$I$10=2)*'Desinversiones'!$G$6:$G$10*(1+('Desinversiones'!$E$6:$E$10="CRC")*N($F$8)+('Desinversiones'!$E$6:$E$10<>"CRC")*$F$9)^(D37-1)) -> 0 | AD37: =SUMPRODUCT(('Desinversiones'!$H$6:$H$10=B37)*('Desinversiones'!$I$6:$I$10=3)*'Desinversiones'!$G$6:$G$10*(1+('Desinversiones'!$E$6:$E$10="CRC")*N($F$8)+('Desinversiones'!$E$6:$E$10<>"CRC")*$F$9)^(D37-1)) -> 196065 | AE37: =SUM(AB37:AD37) -> 196065 | AF37: =AE37 -> 196065 | AG37: =AJ36 -> 564281 | AH37: =AG37*$F$13 -> 33051 | AI37: =AA37+AF37 -> 179487 | AJ37: =AG37+AH37+AI37+AM37 -> 776819 | AK37: =AJ37/(1+$F$9)^(D37-1+$F$24/12) -> 588650 | AL37: =IF(AG37<=0,0,MAX(0,-AI37)/AG37) -> 0 | AM37: =MAX(0,-(AG37+AH37+AI37)) -> 0
B38: =B37+1 -> 2034 | C38: =C37+1 -> 54 | D38: =D37+1 -> 9 | E38: =IF(D38<=$F$19,"Acumulación","Retiro") -> Acumulación | F38: =IF(D38<=$P$7,$N$7*12*(1+IF($M$7="CRC",N($F$8),$F$9))^(D38-1),0) -> 97782 | G38: =IF(D38<=$P$8,$N$8*12*(1+IF($M$8="CRC",N($F$8),$F$9))^(D38-1),0) -> 0 | H38: =IF(AND($N$9>0,D38>=$O$9,D38<=$P$9),$N$9*12*(1+IF($M$9="CRC",N($F$8),$F$9))^(D38-1),0) -> 18108 | I38: =SUMPRODUCT(('Ingresos'!$H$14:$H$17>=B38)*'Ingresos'!$G$14:$G$17*(1+('Ingresos'!$E$14:$E$17="CRC")*N($F$8)+('Ingresos'!$E$14:$E$17<>"CRC")*$F$9)^(D38-1))*12 -> 0 | J38: =IF(AND($N$10>0,D38>=N($O$10)),$N$10*12*(1+IF($M$10="CRC",N($F$8),$F$9))^(N($O$10)-1)*(1+N($F$10))^(D38-N($O$10))*IF(D38=N($O$10),IF(AND(ISNUMBER($F$21),N($F$20)>=$C$30),(12-$F$21)/12,1),1),0) -> 0 | K38: ='Pensiones'!T27 -> 0 | L38: ='Pensiones'!U27 -> 0 | M38: =SUM(F38:L38) -> 115889 | N38: =SUMPRODUCT(('Ingresos'!$H$22:$H$26=B38)*'Ingresos'!$G$22:$G$26*(1+('Ingresos'!$E$22:$E$26="CRC")*N($F$8)+('Ingresos'!$E$22:$E$26<>"CRC")*$F$9)^(D38-1)) -> 0 | O38: ='Pensiones'!S27 -> 0 | P38: =SUM(N38:O38) -> 0 | Q38: =M38+P38 -> 115889 | R38: =$W$7*12*(N($F$22)*(1+$F$9)^(D38-1)+(1-N($F$22))*(1+N($F$8))^(D38-1))*IF(D38>$F$19,$F$18,1) -> 89633 | S38: =SUMPRODUCT(('Gastos'!$H$14:$H$17<=B38)*('Gastos'!$H$14:$H$17+'Gastos'!$I$14:$I$17>B38)*'Gastos'!$G$14:$G$17*(1+('Gastos'!$E$14:$E$17="CRC")*N($F$8)+('Gastos'!$E$14:$E$17<>"CRC")*$F$9)^(D38-1)) -> 16297 | T38: =$W$10*(1+IF($V$10="CRC",N($F$8),$F$9))^(D38-1) -> 4074 | U38: =(IF(D38<=$X$11,$W$11*12,0)+IF('Gastos'!$G$28="Sí",0,SUMPRODUCT(('Gastos'!$H$22:$H$26>=B38)*'Gastos'!$G$22:$G$26)*12)+SUMPRODUCT(('Gastos'!$H$43:$H$45<=B38)*('Gastos'!$H$43:$H$45+'Gastos'!$I$43:$I$45-1>=B38)*'Gastos'!$K$43:$K$45)) -> 14400 | V38: =SUM(R38:U38) -> 124404 | W38: =SUMPRODUCT(('Gastos'!$I$33:$I$37=1)*('Gastos'!$H$33:$H$37=B38)*'Gastos'!$G$33:$G$37*(1+('Gastos'!$E$33:$E$37="CRC")*N($F$8)+('Gastos'!$E$33:$E$37<>"CRC")*$F$9)^(D38-1))+SUMPRODUCT(('Gastos'!$I$33:$I$37=2)*('Gastos'!$H$33:$H$37<=B38)*'Gastos'!$G$33:$G$37*(1+('Gastos'!$E$33:$E$37="CRC")*N($F$8)+('Gastos'!$E$33:$E$37<>"CRC")*$F$9)^(D38-1))+SUMPRODUCT(('Retiros del portafolio'!$H$15:$H$18=B38)*'Retiros del portafolio'!$G$15:$G$18*(1+('Retiros del portafolio'!$E$15:$E$18="CRC")*N($F$8)+('Retiros del portafolio'!$E$15:$E$18<>"CRC")*$F$9)^(D38-1)) -> 8148 | X38: =SUMPRODUCT(('Retiros del portafolio'!$H$6:$H$9=B38)*'Retiros del portafolio'!$G$6:$G$9*(1+('Retiros del portafolio'!$E$6:$E$9="CRC")*N($F$8)+('Retiros del portafolio'!$E$6:$E$9<>"CRC")*$F$9)^(D38-1)) -> 0 | Y38: =W38+X38 -> 8148 | Z38: =V38+Y38 -> 132553 | AA38: =Q38-Z38 -> -16663 | AB38: =SUMPRODUCT(('Desinversiones'!$H$6:$H$10=B38)*('Desinversiones'!$I$6:$I$10=1)*'Desinversiones'!$G$6:$G$10*(1+('Desinversiones'!$E$6:$E$10="CRC")*N($F$8)+('Desinversiones'!$E$6:$E$10<>"CRC")*$F$9)^(D38-1)) -> 0 | AC38: =SUMPRODUCT(('Desinversiones'!$H$6:$H$10=B38)*('Desinversiones'!$I$6:$I$10=2)*'Desinversiones'!$G$6:$G$10*(1+('Desinversiones'!$E$6:$E$10="CRC")*N($F$8)+('Desinversiones'!$E$6:$E$10<>"CRC")*$F$9)^(D38-1)) -> 0 | AD38: =SUMPRODUCT(('Desinversiones'!$H$6:$H$10=B38)*('Desinversiones'!$I$6:$I$10=3)*'Desinversiones'!$G$6:$G$10*(1+('Desinversiones'!$E$6:$E$10="CRC")*N($F$8)+('Desinversiones'!$E$6:$E$10<>"CRC")*$F$9)^(D38-1)) -> 0 | AE38: =SUM(AB38:AD38) -> 0 | AF38: =AE38 -> 0 | AG38: =AJ37 -> 776819 | AH38: =AG38*$F$13 -> 45500 | AI38: =AA38+AF38 -> -16663 | AJ38: =AG38+AH38+AI38+AM38 -> 805656 | AK38: =AJ38/(1+$F$9)^(D38-1+$F$24/12) -> 587586 | AL38: =IF(AG38<=0,0,MAX(0,-AI38)/AG38) -> 0.021450893 | AM38: =MAX(0,-(AG38+AH38+AI38)) -> 0
B39: =B38+1 -> 2035 | C39: =C38+1 -> 55 | D39: =D38+1 -> 10 | E39: =IF(D39<=$F$19,"Acumulación","Retiro") -> Acumulación | F39: =IF(D39<=$P$7,$N$7*12*(1+IF($M$7="CRC",N($F$8),$F$9))^(D39-1),0) -> 101595 | G39: =IF(D39<=$P$8,$N$8*12*(1+IF($M$8="CRC",N($F$8),$F$9))^(D39-1),0) -> 0 | H39: =IF(AND($N$9>0,D39>=$O$9,D39<=$P$9),$N$9*12*(1+IF($M$9="CRC",N($F$8),$F$9))^(D39-1),0) -> 18814 | I39: =SUMPRODUCT(('Ingresos'!$H$14:$H$17>=B39)*'Ingresos'!$G$14:$G$17*(1+('Ingresos'!$E$14:$E$17="CRC")*N($F$8)+('Ingresos'!$E$14:$E$17<>"CRC")*$F$9)^(D39-1))*12 -> 0 | J39: =IF(AND($N$10>0,D39>=N($O$10)),$N$10*12*(1+IF($M$10="CRC",N($F$8),$F$9))^(N($O$10)-1)*(1+N($F$10))^(D39-N($O$10))*IF(D39=N($O$10),IF(AND(ISNUMBER($F$21),N($F$20)>=$C$30),(12-$F$21)/12,1),1),0) -> 0 | K39: ='Pensiones'!T28 -> 0 | L39: ='Pensiones'!U28 -> 0 | M39: =SUM(F39:L39) -> 120409 | N39: =SUMPRODUCT(('Ingresos'!$H$22:$H$26=B39)*'Ingresos'!$G$22:$G$26*(1+('Ingresos'!$E$22:$E$26="CRC")*N($F$8)+('Ingresos'!$E$22:$E$26<>"CRC")*$F$9)^(D39-1)) -> 0 | O39: ='Pensiones'!S28 -> 0 | P39: =SUM(N39:O39) -> 0 | Q39: =M39+P39 -> 120409 | R39: =$W$7*12*(N($F$22)*(1+$F$9)^(D39-1)+(1-N($F$22))*(1+N($F$8))^(D39-1))*IF(D39>$F$19,$F$18,1) -> 93129 | S39: =SUMPRODUCT(('Gastos'!$H$14:$H$17<=B39)*('Gastos'!$H$14:$H$17+'Gastos'!$I$14:$I$17>B39)*'Gastos'!$G$14:$G$17*(1+('Gastos'!$E$14:$E$17="CRC")*N($F$8)+('Gastos'!$E$14:$E$17<>"CRC")*$F$9)^(D39-1)) -> 0 | T39: =$W$10*(1+IF($V$10="CRC",N($F$8),$F$9))^(D39-1) -> 4233 | U39: =(IF(D39<=$X$11,$W$11*12,0)+IF('Gastos'!$G$28="Sí",0,SUMPRODUCT(('Gastos'!$H$22:$H$26>=B39)*'Gastos'!$G$22:$G$26)*12)+SUMPRODUCT(('Gastos'!$H$43:$H$45<=B39)*('Gastos'!$H$43:$H$45+'Gastos'!$I$43:$I$45-1>=B39)*'Gastos'!$K$43:$K$45)) -> 14400 | V39: =SUM(R39:U39) -> 111762 | W39: =SUMPRODUCT(('Gastos'!$I$33:$I$37=1)*('Gastos'!$H$33:$H$37=B39)*'Gastos'!$G$33:$G$37*(1+('Gastos'!$E$33:$E$37="CRC")*N($F$8)+('Gastos'!$E$33:$E$37<>"CRC")*$F$9)^(D39-1))+SUMPRODUCT(('Gastos'!$I$33:$I$37=2)*('Gastos'!$H$33:$H$37<=B39)*'Gastos'!$G$33:$G$37*(1+('Gastos'!$E$33:$E$37="CRC")*N($F$8)+('Gastos'!$E$33:$E$37<>"CRC")*$F$9)^(D39-1))+SUMPRODUCT(('Retiros del portafolio'!$H$15:$H$18=B39)*'Retiros del portafolio'!$G$15:$G$18*(1+('Retiros del portafolio'!$E$15:$E$18="CRC")*N($F$8)+('Retiros del portafolio'!$E$15:$E$18<>"CRC")*$F$9)^(D39-1)) -> 8466 | X39: =SUMPRODUCT(('Retiros del portafolio'!$H$6:$H$9=B39)*'Retiros del portafolio'!$G$6:$G$9*(1+('Retiros del portafolio'!$E$6:$E$9="CRC")*N($F$8)+('Retiros del portafolio'!$E$6:$E$9<>"CRC")*$F$9)^(D39-1)) -> 0 | Y39: =W39+X39 -> 8466 | Z39: =V39+Y39 -> 120228 | AA39: =Q39-Z39 -> 181 | AB39: =SUMPRODUCT(('Desinversiones'!$H$6:$H$10=B39)*('Desinversiones'!$I$6:$I$10=1)*'Desinversiones'!$G$6:$G$10*(1+('Desinversiones'!$E$6:$E$10="CRC")*N($F$8)+('Desinversiones'!$E$6:$E$10<>"CRC")*$F$9)^(D39-1)) -> 0 | AC39: =SUMPRODUCT(('Desinversiones'!$H$6:$H$10=B39)*('Desinversiones'!$I$6:$I$10=2)*'Desinversiones'!$G$6:$G$10*(1+('Desinversiones'!$E$6:$E$10="CRC")*N($F$8)+('Desinversiones'!$E$6:$E$10<>"CRC")*$F$9)^(D39-1)) -> 0 | AD39: =SUMPRODUCT(('Desinversiones'!$H$6:$H$10=B39)*('Desinversiones'!$I$6:$I$10=3)*'Desinversiones'!$G$6:$G$10*(1+('Desinversiones'!$E$6:$E$10="CRC")*N($F$8)+('Desinversiones'!$E$6:$E$10<>"CRC")*$F$9)^(D39-1)) -> 0 | AE39: =SUM(AB39:AD39) -> 0 | AF39: =AE39 -> 0 | AG39: =AJ38 -> 805656 | AH39: =AG39*$F$13 -> 47189 | AI39: =AA39+AF39 -> 181 | AJ39: =AG39+AH39+AI39+AM39 -> 853026 | AK39: =AJ39/(1+$F$9)^(D39-1+$F$24/12) -> 598781 | AL39: =IF(AG39<=0,0,MAX(0,-AI39)/AG39) -> 0 | AM39: =MAX(0,-(AG39+AH39+AI39)) -> 0
B40: =B39+1 -> 2036 | C40: =C39+1 -> 56 | D40: =D39+1 -> 11 | E40: =IF(D40<=$F$19,"Acumulación","Retiro") -> Acumulación | F40: =IF(D40<=$P$7,$N$7*12*(1+IF($M$7="CRC",N($F$8),$F$9))^(D40-1),0) -> 105557 | G40: =IF(D40<=$P$8,$N$8*12*(1+IF($M$8="CRC",N($F$8),$F$9))^(D40-1),0) -> 0 | H40: =IF(AND($N$9>0,D40>=$O$9,D40<=$P$9),$N$9*12*(1+IF($M$9="CRC",N($F$8),$F$9))^(D40-1),0) -> 19548 | I40: =SUMPRODUCT(('Ingresos'!$H$14:$H$17>=B40)*'Ingresos'!$G$14:$G$17*(1+('Ingresos'!$E$14:$E$17="CRC")*N($F$8)+('Ingresos'!$E$14:$E$17<>"CRC")*$F$9)^(D40-1))*12 -> 0 | J40: =IF(AND($N$10>0,D40>=N($O$10)),$N$10*12*(1+IF($M$10="CRC",N($F$8),$F$9))^(N($O$10)-1)*(1+N($F$10))^(D40-N($O$10))*IF(D40=N($O$10),IF(AND(ISNUMBER($F$21),N($F$20)>=$C$30),(12-$F$21)/12,1),1),0) -> 0 | K40: ='Pensiones'!T29 -> 0 | L40: ='Pensiones'!U29 -> 0 | M40: =SUM(F40:L40) -> 125105 | N40: =SUMPRODUCT(('Ingresos'!$H$22:$H$26=B40)*'Ingresos'!$G$22:$G$26*(1+('Ingresos'!$E$22:$E$26="CRC")*N($F$8)+('Ingresos'!$E$22:$E$26<>"CRC")*$F$9)^(D40-1)) -> 0 | O40: ='Pensiones'!S29 -> 0 | P40: =SUM(N40:O40) -> 0 | Q40: =M40+P40 -> 125105 | R40: =$W$7*12*(N($F$22)*(1+$F$9)^(D40-1)+(1-N($F$22))*(1+N($F$8))^(D40-1))*IF(D40>$F$19,$F$18,1) -> 96761 | S40: =SUMPRODUCT(('Gastos'!$H$14:$H$17<=B40)*('Gastos'!$H$14:$H$17+'Gastos'!$I$14:$I$17>B40)*'Gastos'!$G$14:$G$17*(1+('Gastos'!$E$14:$E$17="CRC")*N($F$8)+('Gastos'!$E$14:$E$17<>"CRC")*$F$9)^(D40-1)) -> 0 | T40: =$W$10*(1+IF($V$10="CRC",N($F$8),$F$9))^(D40-1) -> 4398 | U40: =(IF(D40<=$X$11,$W$11*12,0)+IF('Gastos'!$G$28="Sí",0,SUMPRODUCT(('Gastos'!$H$22:$H$26>=B40)*'Gastos'!$G$22:$G$26)*12)+SUMPRODUCT(('Gastos'!$H$43:$H$45<=B40)*('Gastos'!$H$43:$H$45+'Gastos'!$I$43:$I$45-1>=B40)*'Gastos'!$K$43:$K$45)) -> 14400 | V40: =SUM(R40:U40) -> 115559 | W40: =SUMPRODUCT(('Gastos'!$I$33:$I$37=1)*('Gastos'!$H$33:$H$37=B40)*'Gastos'!$G$33:$G$37*(1+('Gastos'!$E$33:$E$37="CRC")*N($F$8)+('Gastos'!$E$33:$E$37<>"CRC")*$F$9)^(D40-1))+SUMPRODUCT(('Gastos'!$I$33:$I$37=2)*('Gastos'!$H$33:$H$37<=B40)*'Gastos'!$G$33:$G$37*(1+('Gastos'!$E$33:$E$37="CRC")*N($F$8)+('Gastos'!$E$33:$E$37<>"CRC")*$F$9)^(D40-1))+SUMPRODUCT(('Retiros del portafolio'!$H$15:$H$18=B40)*'Retiros del portafolio'!$G$15:$G$18*(1+('Retiros del portafolio'!$E$15:$E$18="CRC")*N($F$8)+('Retiros del portafolio'!$E$15:$E$18<>"CRC")*$F$9)^(D40-1)) -> 8796 | X40: =SUMPRODUCT(('Retiros del portafolio'!$H$6:$H$9=B40)*'Retiros del portafolio'!$G$6:$G$9*(1+('Retiros del portafolio'!$E$6:$E$9="CRC")*N($F$8)+('Retiros del portafolio'!$E$6:$E$9<>"CRC")*$F$9)^(D40-1)) -> 0 | Y40: =W40+X40 -> 8796 | Z40: =V40+Y40 -> 124355 | AA40: =Q40-Z40 -> 749 | AB40: =SUMPRODUCT(('Desinversiones'!$H$6:$H$10=B40)*('Desinversiones'!$I$6:$I$10=1)*'Desinversiones'!$G$6:$G$10*(1+('Desinversiones'!$E$6:$E$10="CRC")*N($F$8)+('Desinversiones'!$E$6:$E$10<>"CRC")*$F$9)^(D40-1)) -> 0 | AC40: =SUMPRODUCT(('Desinversiones'!$H$6:$H$10=B40)*('Desinversiones'!$I$6:$I$10=2)*'Desinversiones'!$G$6:$G$10*(1+('Desinversiones'!$E$6:$E$10="CRC")*N($F$8)+('Desinversiones'!$E$6:$E$10<>"CRC")*$F$9)^(D40-1)) -> 0 | AD40: =SUMPRODUCT(('Desinversiones'!$H$6:$H$10=B40)*('Desinversiones'!$I$6:$I$10=3)*'Desinversiones'!$G$6:$G$10*(1+('Desinversiones'!$E$6:$E$10="CRC")*N($F$8)+('Desinversiones'!$E$6:$E$10<>"CRC")*$F$9)^(D40-1)) -> 0 | AE40: =SUM(AB40:AD40) -> 0 | AF40: =AE40 -> 0 | AG40: =AJ39 -> 853026 | AH40: =AG40*$F$13 -> 49964 | AI40: =AA40+AF40 -> 749 | AJ40: =AG40+AH40+AI40+AM40 -> 903739 | AK40: =AJ40/(1+$F$9)^(D40-1+$F$24/12) -> 610568 | AL40: =IF(AG40<=0,0,MAX(0,-AI40)/AG40) -> 0 | AM40: =MAX(0,-(AG40+AH40+AI40)) -> 0
B41: =B40+1 -> 2037 | C41: =C40+1 -> 57 | D41: =D40+1 -> 12 | E41: =IF(D41<=$F$19,"Acumulación","Retiro") -> Acumulación | F41: =IF(D41<=$P$7,$N$7*12*(1+IF($M$7="CRC",N($F$8),$F$9))^(D41-1),0) -> 109674 | G41: =IF(D41<=$P$8,$N$8*12*(1+IF($M$8="CRC",N($F$8),$F$9))^(D41-1),0) -> 0 | H41: =IF(AND($N$9>0,D41>=$O$9,D41<=$P$9),$N$9*12*(1+IF($M$9="CRC",N($F$8),$F$9))^(D41-1),0) -> 20310 | I41: =SUMPRODUCT(('Ingresos'!$H$14:$H$17>=B41)*'Ingresos'!$G$14:$G$17*(1+('Ingresos'!$E$14:$E$17="CRC")*N($F$8)+('Ingresos'!$E$14:$E$17<>"CRC")*$F$9)^(D41-1))*12 -> 0 | J41: =IF(AND($N$10>0,D41>=N($O$10)),$N$10*12*(1+IF($M$10="CRC",N($F$8),$F$9))^(N($O$10)-1)*(1+N($F$10))^(D41-N($O$10))*IF(D41=N($O$10),IF(AND(ISNUMBER($F$21),N($F$20)>=$C$30),(12-$F$21)/12,1),1),0) -> 0 | K41: ='Pensiones'!T30 -> 0 | L41: ='Pensiones'!U30 -> 0 | M41: =SUM(F41:L41) -> 129984 | N41: =SUMPRODUCT(('Ingresos'!$H$22:$H$26=B41)*'Ingresos'!$G$22:$G$26*(1+('Ingresos'!$E$22:$E$26="CRC")*N($F$8)+('Ingresos'!$E$22:$E$26<>"CRC")*$F$9)^(D41-1)) -> 0 | O41: ='Pensiones'!S30 -> 0 | P41: =SUM(N41:O41) -> 0 | Q41: =M41+P41 -> 129984 | R41: =$W$7*12*(N($F$22)*(1+$F$9)^(D41-1)+(1-N($F$22))*(1+N($F$8))^(D41-1))*IF(D41>$F$19,$F$18,1) -> 100534 | S41: =SUMPRODUCT(('Gastos'!$H$14:$H$17<=B41)*('Gastos'!$H$14:$H$17+'Gastos'!$I$14:$I$17>B41)*'Gastos'!$G$14:$G$17*(1+('Gastos'!$E$14:$E$17="CRC")*N($F$8)+('Gastos'!$E$14:$E$17<>"CRC")*$F$9)^(D41-1)) -> 0 | T41: =$W$10*(1+IF($V$10="CRC",N($F$8),$F$9))^(D41-1) -> 4570 | U41: =(IF(D41<=$X$11,$W$11*12,0)+IF('Gastos'!$G$28="Sí",0,SUMPRODUCT(('Gastos'!$H$22:$H$26>=B41)*'Gastos'!$G$22:$G$26)*12)+SUMPRODUCT(('Gastos'!$H$43:$H$45<=B41)*('Gastos'!$H$43:$H$45+'Gastos'!$I$43:$I$45-1>=B41)*'Gastos'!$K$43:$K$45)) -> 14400 | V41: =SUM(R41:U41) -> 119504 | W41: =SUMPRODUCT(('Gastos'!$I$33:$I$37=1)*('Gastos'!$H$33:$H$37=B41)*'Gastos'!$G$33:$G$37*(1+('Gastos'!$E$33:$E$37="CRC")*N($F$8)+('Gastos'!$E$33:$E$37<>"CRC")*$F$9)^(D41-1))+SUMPRODUCT(('Gastos'!$I$33:$I$37=2)*('Gastos'!$H$33:$H$37<=B41)*'Gastos'!$G$33:$G$37*(1+('Gastos'!$E$33:$E$37="CRC")*N($F$8)+('Gastos'!$E$33:$E$37<>"CRC")*$F$9)^(D41-1))+SUMPRODUCT(('Retiros del portafolio'!$H$15:$H$18=B41)*'Retiros del portafolio'!$G$15:$G$18*(1+('Retiros del portafolio'!$E$15:$E$18="CRC")*N($F$8)+('Retiros del portafolio'!$E$15:$E$18<>"CRC")*$F$9)^(D41-1)) -> 9139 | X41: =SUMPRODUCT(('Retiros del portafolio'!$H$6:$H$9=B41)*'Retiros del portafolio'!$G$6:$G$9*(1+('Retiros del portafolio'!$E$6:$E$9="CRC")*N($F$8)+('Retiros del portafolio'!$E$6:$E$9<>"CRC")*$F$9)^(D41-1)) -> 0 | Y41: =W41+X41 -> 9139 | Z41: =V41+Y41 -> 128644 | AA41: =Q41-Z41 -> 1340 | AB41: =SUMPRODUCT(('Desinversiones'!$H$6:$H$10=B41)*('Desinversiones'!$I$6:$I$10=1)*'Desinversiones'!$G$6:$G$10*(1+('Desinversiones'!$E$6:$E$10="CRC")*N($F$8)+('Desinversiones'!$E$6:$E$10<>"CRC")*$F$9)^(D41-1)) -> 0 | AC41: =SUMPRODUCT(('Desinversiones'!$H$6:$H$10=B41)*('Desinversiones'!$I$6:$I$10=2)*'Desinversiones'!$G$6:$G$10*(1+('Desinversiones'!$E$6:$E$10="CRC")*N($F$8)+('Desinversiones'!$E$6:$E$10<>"CRC")*$F$9)^(D41-1)) -> 0 | AD41: =SUMPRODUCT(('Desinversiones'!$H$6:$H$10=B41)*('Desinversiones'!$I$6:$I$10=3)*'Desinversiones'!$G$6:$G$10*(1+('Desinversiones'!$E$6:$E$10="CRC")*N($F$8)+('Desinversiones'!$E$6:$E$10<>"CRC")*$F$9)^(D41-1)) -> 0 | AE41: =SUM(AB41:AD41) -> 0 | AF41: =AE41 -> 0 | AG41: =AJ40 -> 903739 | AH41: =AG41*$F$13 -> 52934 | AI41: =AA41+AF41 -> 1340 | AJ41: =AG41+AH41+AI41+AM41 -> 958014 | AK41: =AJ41/(1+$F$9)^(D41-1+$F$24/12) -> 622941 | AL41: =IF(AG41<=0,0,MAX(0,-AI41)/AG41) -> 0 | AM41: =MAX(0,-(AG41+AH41+AI41)) -> 0
B42: =B41+1 -> 2038 | C42: =C41+1 -> 58 | D42: =D41+1 -> 13 | E42: =IF(D42<=$F$19,"Acumulación","Retiro") -> Acumulación | F42: =IF(D42<=$P$7,$N$7*12*(1+IF($M$7="CRC",N($F$8),$F$9))^(D42-1),0) -> 113951 | G42: =IF(D42<=$P$8,$N$8*12*(1+IF($M$8="CRC",N($F$8),$F$9))^(D42-1),0) -> 0 | H42: =IF(AND($N$9>0,D42>=$O$9,D42<=$P$9),$N$9*12*(1+IF($M$9="CRC",N($F$8),$F$9))^(D42-1),0) -> 21102 | I42: =SUMPRODUCT(('Ingresos'!$H$14:$H$17>=B42)*'Ingresos'!$G$14:$G$17*(1+('Ingresos'!$E$14:$E$17="CRC")*N($F$8)+('Ingresos'!$E$14:$E$17<>"CRC")*$F$9)^(D42-1))*12 -> 0 | J42: =IF(AND($N$10>0,D42>=N($O$10)),$N$10*12*(1+IF($M$10="CRC",N($F$8),$F$9))^(N($O$10)-1)*(1+N($F$10))^(D42-N($O$10))*IF(D42=N($O$10),IF(AND(ISNUMBER($F$21),N($F$20)>=$C$30),(12-$F$21)/12,1),1),0) -> 0 | K42: ='Pensiones'!T31 -> 0 | L42: ='Pensiones'!U31 -> 0 | M42: =SUM(F42:L42) -> 135053 | N42: =SUMPRODUCT(('Ingresos'!$H$22:$H$26=B42)*'Ingresos'!$G$22:$G$26*(1+('Ingresos'!$E$22:$E$26="CRC")*N($F$8)+('Ingresos'!$E$22:$E$26<>"CRC")*$F$9)^(D42-1)) -> 0 | O42: ='Pensiones'!S31 -> 0 | P42: =SUM(N42:O42) -> 0 | Q42: =M42+P42 -> 135053 | R42: =$W$7*12*(N($F$22)*(1+$F$9)^(D42-1)+(1-N($F$22))*(1+N($F$8))^(D42-1))*IF(D42>$F$19,$F$18,1) -> 104455 | S42: =SUMPRODUCT(('Gastos'!$H$14:$H$17<=B42)*('Gastos'!$H$14:$H$17+'Gastos'!$I$14:$I$17>B42)*'Gastos'!$G$14:$G$17*(1+('Gastos'!$E$14:$E$17="CRC")*N($F$8)+('Gastos'!$E$14:$E$17<>"CRC")*$F$9)^(D42-1)) -> 0 | T42: =$W$10*(1+IF($V$10="CRC",N($F$8),$F$9))^(D42-1) -> 4748 | U42: =(IF(D42<=$X$11,$W$11*12,0)+IF('Gastos'!$G$28="Sí",0,SUMPRODUCT(('Gastos'!$H$22:$H$26>=B42)*'Gastos'!$G$22:$G$26)*12)+SUMPRODUCT(('Gastos'!$H$43:$H$45<=B42)*('Gastos'!$H$43:$H$45+'Gastos'!$I$43:$I$45-1>=B42)*'Gastos'!$K$43:$K$45)) -> 14400 | V42: =SUM(R42:U42) -> 123603 | W42: =SUMPRODUCT(('Gastos'!$I$33:$I$37=1)*('Gastos'!$H$33:$H$37=B42)*'Gastos'!$G$33:$G$37*(1+('Gastos'!$E$33:$E$37="CRC")*N($F$8)+('Gastos'!$E$33:$E$37<>"CRC")*$F$9)^(D42-1))+SUMPRODUCT(('Gastos'!$I$33:$I$37=2)*('Gastos'!$H$33:$H$37<=B42)*'Gastos'!$G$33:$G$37*(1+('Gastos'!$E$33:$E$37="CRC")*N($F$8)+('Gastos'!$E$33:$E$37<>"CRC")*$F$9)^(D42-1))+SUMPRODUCT(('Retiros del portafolio'!$H$15:$H$18=B42)*'Retiros del portafolio'!$G$15:$G$18*(1+('Retiros del portafolio'!$E$15:$E$18="CRC")*N($F$8)+('Retiros del portafolio'!$E$15:$E$18<>"CRC")*$F$9)^(D42-1)) -> 9496 | X42: =SUMPRODUCT(('Retiros del portafolio'!$H$6:$H$9=B42)*'Retiros del portafolio'!$G$6:$G$9*(1+('Retiros del portafolio'!$E$6:$E$9="CRC")*N($F$8)+('Retiros del portafolio'!$E$6:$E$9<>"CRC")*$F$9)^(D42-1)) -> 0 | Y42: =W42+X42 -> 9496 | Z42: =V42+Y42 -> 133099 | AA42: =Q42-Z42 -> 1954 | AB42: =SUMPRODUCT(('Desinversiones'!$H$6:$H$10=B42)*('Desinversiones'!$I$6:$I$10=1)*'Desinversiones'!$G$6:$G$10*(1+('Desinversiones'!$E$6:$E$10="CRC")*N($F$8)+('Desinversiones'!$E$6:$E$10<>"CRC")*$F$9)^(D42-1)) -> 0 | AC42: =SUMPRODUCT(('Desinversiones'!$H$6:$H$10=B42)*('Desinversiones'!$I$6:$I$10=2)*'Desinversiones'!$G$6:$G$10*(1+('Desinversiones'!$E$6:$E$10="CRC")*N($F$8)+('Desinversiones'!$E$6:$E$10<>"CRC")*$F$9)^(D42-1)) -> 0 | AD42: =SUMPRODUCT(('Desinversiones'!$H$6:$H$10=B42)*('Desinversiones'!$I$6:$I$10=3)*'Desinversiones'!$G$6:$G$10*(1+('Desinversiones'!$E$6:$E$10="CRC")*N($F$8)+('Desinversiones'!$E$6:$E$10<>"CRC")*$F$9)^(D42-1)) -> 0 | AE42: =SUM(AB42:AD42) -> 0 | AF42: =AE42 -> 0 | AG42: =AJ41 -> 958014 | AH42: =AG42*$F$13 -> 56113 | AI42: =AA42+AF42 -> 1954 | AJ42: =AG42+AH42+AI42+AM42 -> 1016081 | AK42: =AJ42/(1+$F$9)^(D42-1+$F$24/12) -> 635899 | AL42: =IF(AG42<=0,0,MAX(0,-AI42)/AG42) -> 0 | AM42: =MAX(0,-(AG42+AH42+AI42)) -> 0
... B79: =B78+1 -> 2075 | C79: =C78+1 -> 95 | D79: =D78+1 -> 50 | E79: =IF(D79<=$F$19,"Acumulación","Retiro") -> Retiro | F79: =IF(D79<=$P$7,$N$7*12*(1+IF($M$7="CRC",N($F$8),$F$9))^(D79-1),0) -> 0 | G79: =IF(D79<=$P$8,$N$8*12*(1+IF($M$8="CRC",N($F$8),$F$9))^(D79-1),0) -> 0 | H79: =IF(AND($N$9>0,D79>=$O$9,D79<=$P$9),$N$9*12*(1+IF($M$9="CRC",N($F$8),$F$9))^(D79-1),0) -> 86916 | I79: =SUMPRODUCT(('Ingresos'!$H$14:$H$17>=B79)*'Ingresos'!$G$14:$G$17*(1+('Ingresos'!$E$14:$E$17="CRC")*N($F$8)+('Ingresos'!$E$14:$E$17<>"CRC")*$F$9)^(D79-1))*12 -> 0 | J79: =IF(AND($N$10>0,D79>=N($O$10)),$N$10*12*(1+IF($M$10="CRC",N($F$8),$F$9))^(N($O$10)-1)*(1+N($F$10))^(D79-N($O$10))*IF(D79=N($O$10),IF(AND(ISNUMBER($F$21),N($F$20)>=$C$30),(12-$F$21)/12,1),1),0) -> 59483 | K79: ='Pensiones'!T68 -> 12554 | L79: ='Pensiones'!U68 -> 14740 | M79: =SUM(F79:L79) -> 173694 | N79: =SUMPRODUCT(('Ingresos'!$H$22:$H$26=B79)*'Ingresos'!$G$22:$G$26*(1+('Ingresos'!$E$22:$E$26="CRC")*N($F$8)+('Ingresos'!$E$22:$E$26<>"CRC")*$F$9)^(D79-1)) -> 0 | O79: ='Pensiones'!S68 -> 0 | P79: =SUM(N79:O79) -> 0 | Q79: =M79+P79 -> 173694 | R79: =$W$7*12*(N($F$22)*(1+$F$9)^(D79-1)+(1-N($F$22))*(1+N($F$8))^(D79-1))*IF(D79>$F$19,$F$18,1) -> 430235 | S79: =SUMPRODUCT(('Gastos'!$H$14:$H$17<=B79)*('Gastos'!$H$14:$H$17+'Gastos'!$I$14:$I$17>B79)*'Gastos'!$G$14:$G$17*(1+('Gastos'!$E$14:$E$17="CRC")*N($F$8)+('Gastos'!$E$14:$E$17<>"CRC")*$F$9)^(D79-1)) -> 0 | T79: =$W$10*(1+IF($V$10="CRC",N($F$8),$F$9))^(D79-1) -> 19556 | U79: =(IF(D79<=$X$11,$W$11*12,0)+IF('Gastos'!$G$28="Sí",0,SUMPRODUCT(('Gastos'!$H$22:$H$26>=B79)*'Gastos'!$G$22:$G$26)*12)+SUMPRODUCT(('Gastos'!$H$43:$H$45<=B79)*('Gastos'!$H$43:$H$45+'Gastos'!$I$43:$I$45-1>=B79)*'Gastos'!$K$43:$K$45)) -> 0 | V79: =SUM(R79:U79) -> 449791 | W79: =SUMPRODUCT(('Gastos'!$I$33:$I$37=1)*('Gastos'!$H$33:$H$37=B79)*'Gastos'!$G$33:$G$37*(1+('Gastos'!$E$33:$E$37="CRC")*N($F$8)+('Gastos'!$E$33:$E$37<>"CRC")*$F$9)^(D79-1))+SUMPRODUCT(('Gastos'!$I$33:$I$37=2)*('Gastos'!$H$33:$H$37<=B79)*'Gastos'!$G$33:$G$37*(1+('Gastos'!$E$33:$E$37="CRC")*N($F$8)+('Gastos'!$E$33:$E$37<>"CRC")*$F$9)^(D79-1))+SUMPRODUCT(('Retiros del portafolio'!$H$15:$H$18=B79)*'Retiros del portafolio'!$G$15:$G$18*(1+('Retiros del portafolio'!$E$15:$E$18="CRC")*N($F$8)+('Retiros del portafolio'!$E$15:$E$18<>"CRC")*$F$9)^(D79-1)) -> 39112 | X79: =SUMPRODUCT(('Retiros del portafolio'!$H$6:$H$9=B79)*'Retiros del portafolio'!$G$6:$G$9*(1+('Retiros del portafolio'!$E$6:$E$9="CRC")*N($F$8)+('Retiros del portafolio'!$E$6:$E$9<>"CRC")*$F$9)^(D79-1)) -> 0 | Y79: =W79+X79 -> 39112 | Z79: =V79+Y79 -> 488903 | AA79: =Q79-Z79 -> -315210 | AB79: =SUMPRODUCT(('Desinversiones'!$H$6:$H$10=B79)*('Desinversiones'!$I$6:$I$10=1)*'Desinversiones'!$G$6:$G$10*(1+('Desinversiones'!$E$6:$E$10="CRC")*N($F$8)+('Desinversiones'!$E$6:$E$10<>"CRC")*$F$9)^(D79-1)) -> 0 | AC79: =SUMPRODUCT(('Desinversiones'!$H$6:$H$10=B79)*('Desinversiones'!$I$6:$I$10=2)*'Desinversiones'!$G$6:$G$10*(1+('Desinversiones'!$E$6:$E$10="CRC")*N($F$8)+('Desinversiones'!$E$6:$E$10<>"CRC")*$F$9)^(D79-1)) -> 0 | AD79: =SUMPRODUCT(('Desinversiones'!$H$6:$H$10=B79)*('Desinversiones'!$I$6:$I$10=3)*'Desinversiones'!$G$6:$G$10*(1+('Desinversiones'!$E$6:$E$10="CRC")*N($F$8)+('Desinversiones'!$E$6:$E$10<>"CRC")*$F$9)^(D79-1)) -> 0 | AE79: =SUM(AB79:AD79) -> 0 | AF79: =AE79 -> 0 | AG79: =AJ78 -> 0 | AH79: =AG79*$F$13 -> 0 | AI79: =AA79+AF79 -> -315210 | AJ79: =AG79+AH79+AI79+AM79 -> 0 | AK79: =AJ79/(1+$F$9)^(D79-1+$F$24/12) -> 0 | AL79: =IF(AG79<=0,0,MAX(0,-AI79)/AG79) -> 0 | AM79: =MAX(0,-(AG79+AH79+AI79)) -> 315210
...

Sheet Ingresos
B1: Ingresos · Cliente de ejemplo
